Workbook

Sheet autotagging_moodtheme
A1: TRACK_ID | B1: ARTIST_ID | C1: ALBUM_ID | D1: PATH | E1: DURATION | F1: TAGS | G1: Column1 | H1: _1 | I1: _2 | J1: _3 | K1: _4
A2: track_0000948 | B2: artist_000087 | C2: album_000149 | D2: 48/948.mp3 | E2: 2127 | F2: mood/theme---background
A3: track_0000950 | B3: artist_000087 | C3: album_000149 | D3: 50/950.mp3 | E3: 2480 | F3: mood/theme---background
A4: track_0000951 | B4: artist_000087 | C4: album_000149 | D4: 51/951.mp3 | E4: 1997 | F4: mood/theme---background
A5: track_0002165 | B5: artist_000326 | C5: album_000347 | D5: 65/2165.mp3 | E5: 2290 | F5: mood/theme---film
A6: track_0002263 | B6: artist_000320 | C6: album_000366 | D6: 63/2263.mp3 | E6: 4947 | F6: mood/theme---melancholic
A7: track_0003346 | B7: artist_000517 | C7: album_000521 | D7: 46/3346.mp3 | E7: 1950 | F7: mood/theme---calm | G7: mood/theme---melodic
A8: track_0003347 | B8: artist_000517 | C8: album_000521 | D8: 47/3347.mp3 | E8: 2018 | F8: mood/theme---calm | G8: mood/theme---melodic
A9: track_0003348 | B9: artist_000517 | C9: album_000521 | D9: 48/3348.mp3 | E9: 2533 | F9: mood/theme---calm | G9: mood/theme---melodic
A10: track_0003349 | B10: artist_000517 | C10: album_000521 | D10: 49/3349.mp3 | E10: 2284 | F10: mood/theme---calm | G10: mood/theme---melodic
A11: track_0003350 | B11: artist_000517 | C11: album_000521 | D11: 50/3350.mp3 | E11: 1947 | F11: mood/theme---calm | G11: mood/theme---melodic
A12: track_0003524 | B12: artist_000530 | C12: album_000552 | D12: 24/3524.mp3 | E12: 2661 | F12: mood/theme---melodic
A13: track_0004629 | B13: artist_000087 | C13: album_000718 | D13: 29/4629.mp3 | E13: 1805 | F13: mood/theme---melodic
A14: track_0004631 | B14: artist_000087 | C14: album_000718 | D14: 31/4631.mp3 | E14: 3342 | F14: mood/theme---melodic
A15: track_0004632 | B15: artist_000087 | C15: album_000718 | D15: 32/4632.mp3 | E15: 2943 | F15: mood/theme---background
A16: track_0004638 | B16: artist_000087 | C16: album_000718 | D16: 38/4638.mp3 | E16: 1802 | F16: mood/theme---children
A17: track_0004639 | B17: artist_000087 | C17: album_000718 | D17: 39/4639.mp3 | E17: 1880 | F17: mood/theme---children | G17: mood/theme---relaxing
A18: track_0004640 | B18: artist_000087 | C18: album_000718 | D18: 40/4640.mp3 | E18: 2624 | F18: mood/theme---background
A19: track_0004882 | B19: artist_000696 | C19: album_000751 | D19: 82/4882.mp3 | E19: 2104 | F19: mood/theme---meditative
A20: track_0004883 | B20: artist_000696 | C20: album_000751 | D20: 83/4883.mp3 | E20: 2495 | F20: mood/theme---meditative
A21: track_0004884 | B21: artist_000696 | C21: album_000751 | D21: 84/4884.mp3 | E21: 2207 | F21: mood/theme---meditative
A22: track_0004889 | B22: artist_000696 | C22: album_000751 | D22: 89/4889.mp3 | E22: 1790 | F22: mood/theme---meditative
A23: track_0005083 | B23: artist_000696 | C23: album_000786 | D23: 83/5083.mp3 | E23: 1654 | F23: mood/theme---meditative
A24: track_0005084 | B24: artist_000696 | C24: album_000786 | D24: 84/5084.mp3 | E24: 2057 | F24: mood/theme---cool
A25: track_0005085 | B25: artist_000696 | C25: album_000786 | D25: 85/5085.mp3 | E25: 2520 | F25: mood/theme---cool
A26: track_0005086 | B26: artist_000696 | C26: album_000786 | D26: 86/5086.mp3 | E26: 2350 | F26: mood/theme---cool
A27: track_0005089 | B27: artist_000696 | C27: album_000786 | D27: 89/5089.mp3 | E27: 1028 | F27: mood/theme---cool
A28: track_0005634 | B28: artist_000811 | C28: album_000867 | D28: 34/5634.mp3 | E28: 2331 | F28: mood/theme---documentary | G28: mood/theme---emotional | H28: mood/theme---space
A29: track_0005635 | B29: artist_000811 | C29: album_000867 | D29: 35/5635.mp3 | E29: 2326 | F29: mood/theme---documentary | G29: mood/theme---emotional | H29: mood/theme---space
A30: track_0005636 | B30: artist_000811 | C30: album_000867 | D30: 36/5636.mp3 | E30: 2774 | F30: mood/theme---documentary | G30: mood/theme---emotional | H30: mood/theme---space
A31: track_0005637 | B31: artist_000811 | C31: album_000867 | D31: 37/5637.mp3 | E31: 3350 | F31: mood/theme---documentary | G31: mood/theme---emotional | H31: mood/theme---space
A32: track_0005638 | B32: artist_000811 | C32: album_000867 | D32: 38/5638.mp3 | E32: 2257 | F32: mood/theme---documentary | G32: mood/theme---emotional | H32: mood/theme---space
A33: track_0005640 | B33: artist_000811 | C33: album_000867 | D33: 40/5640.mp3 | E33: 2273 | F33: mood/theme---documentary | G33: mood/theme---emotional | H33: mood/theme---space
A34: track_0005641 | B34: artist_000811 | C34: album_000867 | D34: 41/5641.mp3 | E34: 2151 | F34: mood/theme---documentary | G34: mood/theme---emotional | H34: mood/theme---space
A35: track_0005642 | B35: artist_000811 | C35: album_000867 | D35: 42/5642.mp3 | E35: 2173 | F35: mood/theme---documentary | G35: mood/theme---emotional | H35: mood/theme---space
A36: track_0005643 | B36: artist_000811 | C36: album_000867 | D36: 43/5643.mp3 | E36: 2316 | F36: mood/theme---documentary | G36: mood/theme---emotional | H36: mood/theme---space
A37: track_0006247 | B37: artist_000811 | C37: album_000960 | D37: 47/6247.mp3 | E37: 3817 | F37: mood/theme---emotional
A38: track_0006248 | B38: artist_000811 | C38: album_000960 | D38: 48/6248.mp3 | E38: 2498 | F38: mood/theme---documentary
A39: track_0006249 | B39: artist_000811 | C39: album_000960 | D39: 49/6249.mp3 | E39: 3647 | F39: mood/theme---documentary | G39: mood/theme---emotional
A40: track_0006250 | B40: artist_000811 | C40: album_000960 | D40: 50/6250.mp3 | E40: 2384 | F40: mood/theme---documentary | G40: mood/theme---emotional
...

Sheet PROC
A1: TRACK_ID | B1: ARTIST_ID | C1: ALBUM_ID | D1: PATH | E1: DURATION | F1: TAGS
A2: =autotagging_moodtheme!A2 -> track_0000948 | B2: {=autotagging_moodtheme__2[ARTIST_ID]} -> artist_000087 | C2: {=autotagging_moodtheme__2[ALBUM_ID]} -> album_000149 | D2: {=autotagging_moodtheme__2[PATH]} -> 48/948.mp3 | E2: {=autotagging_moodtheme__2[DURATION]} -> 2127 | F2: =_xlfn.TEXTJOIN("+", TRUE(), autotagging_moodtheme__2[[#This Row],[TAGS]:[_4]]) -> mood/theme---background
A3: =autotagging_moodtheme!A3 -> track_0000950 | B3: artist_000087 | C3: album_000149 | D3: 50/950.mp3 | E3: 2480 | F3: =_xlfn.TEXTJOIN("+", TRUE(), autotagging_moodtheme__2[[#This Row],[TAGS]:[_4]]) -> mood/theme---background
A4: =autotagging_moodtheme!A4 -> track_0000951 | B4: artist_000087 | C4: album_000149 | D4: 51/951.mp3 | E4: 1997 | F4: =_xlfn.TEXTJOIN("+", TRUE(), autotagging_moodtheme__2[[#This Row],[TAGS]:[_4]]) -> mood/theme---background
A5: =autotagging_moodtheme!A5 -> track_0002165 | B5: artist_000326 | C5: album_000347 | D5: 65/2165.mp3 | E5: 2290 | F5: =_xlfn.TEXTJOIN("+", TRUE(), autotagging_moodtheme__2[[#This Row],[TAGS]:[_4]]) -> mood/theme---film
A6: =autotagging_moodtheme!A6 -> track_0002263 | B6: artist_000320 | C6: album_000366 | D6: 63/2263.mp3 | E6: 4947 | F6: =_xlfn.TEXTJOIN("+", TRUE(), autotagging_moodtheme__2[[#This Row],[TAGS]:[_4]]) -> mood/theme---melancholic
A7: =autotagging_moodtheme!A7 -> track_0003346 | B7: artist_000517 | C7: album_000521 | D7: 46/3346.mp3 | E7: 1950 | F7: =_xlfn.TEXTJOIN("+", TRUE(), autotagging_moodtheme__2[[#This Row],[TAGS]:[_4]]) -> mood/theme---calm+mood/theme---melodic
A8: =autotagging_moodtheme!A8 -> track_0003347 | B8: artist_000517 | C8: album_000521 | D8: 47/3347.mp3 | E8: 2018 | F8: =_xlfn.TEXTJOIN("+", TRUE(), autotagging_moodtheme__2[[#This Row],[TAGS]:[_4]]) -> mood/theme---calm+mood/theme---melodic
A9: =autotagging_moodtheme!A9 -> track_0003348 | B9: artist_000517 | C9: album_000521 | D9: 48/3348.mp3 | E9: 2533 | F9: =_xlfn.TEXTJOIN("+", TRUE(), autotagging_moodtheme__2[[#This Row],[TAGS]:[_4]]) -> mood/theme---calm+mood/theme---melodic
A10: =autotagging_moodtheme!A10 -> track_0003349 | B10: artist_000517 | C10: album_000521 | D10: 49/3349.mp3 | E10: 2284 | F10: =_xlfn.TEXTJOIN("+", TRUE(), autotagging_moodtheme__2[[#This Row],[TAGS]:[_4]]) -> mood/theme---calm+mood/theme---melodic
A11: =autotagging_moodtheme!A11 -> track_0003350 | B11: artist_000517 | C11: album_000521 | D11: 50/3350.mp3 | E11: 1947 | F11: =_xlfn.TEXTJOIN("+", TRUE(), autotagging_moodtheme__2[[#This Row],[TAGS]:[_4]]) -> mood/theme---calm+mood/theme---melodic
A12: =autotagging_moodtheme!A12 -> track_0003524 | B12: artist_000530 | C12: album_000552 | D12: 24/3524.mp3 | E12: 2661 | F12: =_xlfn.TEXTJOIN("+", TRUE(), autotagging_moodtheme__2[[#This Row],[TAGS]:[_4]]) -> mood/theme---melodic
A13: =autotagging_moodtheme!A13 -> track_0004629 | B13: artist_000087 | C13: album_000718 | D13: 29/4629.mp3 | E13: 1805 | F13: =_xlfn.TEXTJOIN("+", TRUE(), autotagging_moodtheme__2[[#This Row],[TAGS]:[_4]]) -> mood/theme---melodic
A14: =autotagging_moodtheme!A14 -> track_0004631 | B14: artist_000087 | C14: album_000718 | D14: 31/4631.mp3 | E14: 3342 | F14: =_xlfn.TEXTJOIN("+", TRUE(), autotagging_moodtheme__2[[#This Row],[TAGS]:[_4]]) -> mood/theme---melodic
... A18487: =autotagging_moodtheme!A18487 -> track_1422060 | B18487: artist_496314 | C18487: album_165847 | D18487: 60/1422060.mp3 | E18487: 3360 | F18487: =_xlfn.TEXTJOIN("+", TRUE(), autotagging_moodtheme__2[[#This Row],[TAGS]:[_4]]) -> mood/theme---advertising+mood/theme---dramatic+mood/theme---epic+mood/theme---movie
