Workbook

Sheet DATA
H1: Ini dijelaskan di Bab 2.2.4.1 | K1: Normalisasi per fitur/pita mel
B2: INPUT | C2: dB | I2: Z-SCORE
B3: 1 | C3: 2 | D3: 3 | E3: 4 | F3: 5 | I3: 1 | J3: 2 | K3: 3 | L3: 4 | M3: 5
A4: 1 | B4: -17.455579 | C4: 2.1746577 | D4: 2.367183 | E4: -16.994306 | F4: -31.521326 | H4: 1 | I4: =(B4-I$10)/I$11 -> 0.098070128 | J4: =(C4-J$10)/J$11 -> 0.76989837 | K4: =(D4-K$10)/K$11 -> 1.0888675 | L4: =(E4-L$10)/L$11 -> 0.41864133 | M4: =(F4-M$10)/M$11 -> -0.54807215
A5: 2 | B5: -13.55774 | C5: 1.9652145 | D5: -47.671875 | E5: -5.831727 | F5: -55.399592 | H5: 2 | I5: =(B5-I$10)/I$11 -> 0.39479458 | J5: =(C5-J$10)/J$11 -> 0.76298403 | K5: =(D5-K$10)/K$11 -> -1.5092547 | L5: =(E5-L$10)/L$11 -> 0.78695236 | M5: =(F5-M$10)/M$11 -> -1.6514231
A6: 3 | B6: -2.1784123 | C6: 9.7535512 | D6: -14.569788 | E6: -76.581514 | F6: -30.697405 | H6: 3 | I6: =(B6-I$10)/I$11 -> 1.2610502 | J6: =(C6-J$10)/J$11 -> 1.0201002 | K6: =(D6-K$10)/K$11 -> 0.20946803 | L6: =(E6-L$10)/L$11 -> -1.5474479 | M6: =(F6-M$10)/M$11 -> -0.51000095
A7: 4 | B7: -43.897392 | C7: -50.379692 | D7: -32.779354 | E7: -66.49576 | F7: -6.4124977 | H7: 4 | I7: =(B7-I$10)/I$11 -> -1.9148228 | J7: =(C7-J$10)/J$11 -> -0.96507706 | K7: =(D7-K$10)/K$11 -> -0.73600695 | L7: =(E7-L$10)/L$11 -> -1.2146669 | M7: =(F7-M$10)/M$11 -> 0.61213976
A8: 5 | B8: -10.70635 | C8: -72.225023 | D8: -26.179162 | E8: 1.4530419 | F8: 8.7227731 | H8: 5 | I8: =(B8-I$10)/I$11 -> 0.61185768 | J8: =(C8-J$10)/J$11 -> -1.6862565 | K8: =(D8-K$10)/K$11 -> -0.39331256 | L8: =(E8-L$10)/L$11 -> 1.0273144 | M8: =(F8-M$10)/M$11 -> 1.3115002
A9: 6 | B9: -24.667626 | C9: -18.167267 | D9: 7.2085165 | E9: -13.643349 | F9: -2.6529983 | H9: 6 | I9: =(B9-I$10)/I$11 -> -0.4509497 | J9: =(C9-J$10)/J$11 -> 0.098350912 | K9: =(D9-K$10)/K$11 -> 1.3402387 | L9: =(E9-L$10)/L$11 -> 0.52920668 | M9: =(F9-M$10)/M$11 -> 0.78585619
H10: avg | I10: =AVERAGE(B4:B9) -> -18.74385 | J10: =AVERAGE(C4:C9) -> -21.146426 | K10: =AVERAGE(D4:D9) -> -18.60408 | L10: =AVERAGE(E4:E9) -> -29.682269 | M10: =AVERAGE(F4:F9) -> -19.660174
H11: std_dev | I11: =_xlfn.STDEV.P(B4:B9) -> 13.136224 | J11: =_xlfn.STDEV.P(C4:C9) -> 30.29112 | K11: =_xlfn.STDEV.P(D4:D9) -> 19.259701 | L11: =_xlfn.STDEV.P(E4:E9) -> 30.307479 | M11: =_xlfn.STDEV.P(F4:F9) -> 21.641588
B12: PREDIKSI | E12: LABEL
B13: gembira | C13: sedih | D13: tegang
B14: 1 | C14: 2 | D14: 3 | I14: COUNTIF
A15: 1 | B15: Akan dihitung | E15: gembira | F15: tegang | I15: p_n | J15: n=1,2,3
A16: 2 | B16: Dummy | E16: gembira | F16: sedih | H16: gembira | I16: =J16/$J$19 -> 0.11538462 | J16: 3
A17: 3 | E17: tegang | F17: sedih | H17: sedih | I17: =J17/$J$19 -> 0.61538462 | J17: 16
A18: 4 | E18: gembira | H18: tegang | I18: =J18/$J$19 -> 0.26923077 | J18: 7
B19: >> LIHAT SHEET "EVAL" | J19: =SUM(J16:J18) -> 26

Sheet FRONTEND
A2: {=DATA!H2:M9} -> 0 | B2: Z-SCORE | C2: 0 | D2: 0 | E2: 0 | F2: 0 | M2: FEED-FORWARD | T2: FEED-FORWARD
A3: 0 | B3: 1 | C3: 2 | D3: 3 | E3: 4 | F3: 5 | M3: KONVOLUSI VERTIKAL | T3: KONVOLUSI HORIZONTAL
A4: 1 | B4: 0.098070128 | C4: 0.76989837 | D4: 1.0888675 | E4: 0.41864133 | F4: -0.54807215
A5: 2 | B5: 0.39479458 | C5: 0.76298403 | D5: -1.5092547 | E5: 0.78695236 | F5: -1.6514231 | M5: KERNEL | T5: KERNEL | W5: BIAS
A6: 3 | B6: 1.2610502 | C6: 1.0201002 | D6: 0.20946803 | E6: -1.5474479 | F6: -0.51000095 | M6: 1 | N6: 2 | O6: 3 | T6: 1 | W6: 1
A7: 4 | B7: -1.9148228 | C7: -0.96507706 | D7: -0.73600695 | E7: -1.2146669 | F7: 0.61213976 | L7: 1 | M7: -0.512 | N7: 0.897 | O7: -0.523 | S7: 1 | T7: 0.122 | V7: 1 | W7: 1
A8: 5 | B8: 0.61185768 | C8: -1.6862565 | D8: -0.39331256 | E8: 1.0273144 | F8: 1.3115002 | L8: 2 | M8: 0.122 | N8: -0.204 | O8: -0.74 | S8: 2 | T8: 0.516
A9: 6 | B9: -0.4509497 | C9: 0.098350912 | D9: 1.3402387 | E9: 0.52920668 | F9: 0.78585619 | L9: 3 | M9: 0.742 | N9: 0.805 | O9: -0.977 | S9: 3 | T9: -0.977
L10: 4 | M10: 0.782 | N10: 0.516 | O10: -0.914
B11: INPUT PADDED | L11: 5 | M11: 0.409 | N11: -0.438 | O11: 0.293 | T11: HASIL | U11: Pers 2.15
B12: 1 | C12: 2 | D12: 3 | E12: 4 | F12: 5 | G12: 6 | H12: 7 | T12: 1
A13: 1 | B13: 0 | C13: 0 | D13: 0 | E13: 0 | F13: 0 | G13: 0 | H13: 0 | M13: BIAS | S13: 1 | T13: {=SUM(B35:B37*$T$7:$T$9)+$W$7} -> 1.4261842
A14: 2 | B14: 0 | C14: 0 | D14: 0 | E14: 0 | F14: 0 | G14: 0 | H14: 0 | M14: 1 | S14: 2 | T14: {=SUM(B36:B38*$T$7:$T$9)+$W$7} -> 0.83446165
A15: 3 | B15: 0 | C15: {=B4:F9} -> 0.098070128 | D15: 0.76989837 | E15: 1.0888675 | F15: 0.41864133 | G15: -0.54807215 | H15: 0 | L15: 1 | M15: 1 | S15: 3 | T15: {=SUM(B37:B39*$T$7:$T$9)+$W$7} -> 1.839316
A16: 4 | B16: 0 | C16: 0.39479458 | D16: 0.76298403 | E16: -1.5092547 | F16: 0.78695236 | G16: -1.6514231 | H16: 0 | S16: 4 | T16: {=SUM(B38:B40*$T$7:$T$9)+$W$7} -> 0.40501336
A17: 5 | B17: 0 | C17: 1.2610502 | D17: 1.0201002 | E17: 0.20946803 | F17: -1.5474479 | G17: -0.51000095 | H17: 0 | M17: HASIL | N17: Pers 2.8 | S17: 5 | T17: {=SUM(B39:B41*$T$7:$T$9)+$W$7} -> 0.53701995
A18: 6 | B18: 0 | C18: -1.9148228 | D18: -0.96507706 | E18: -0.73600695 | F18: -1.2146669 | G18: 0.61213976 | H18: 0 | M18: 1 | N18: 2 | O18: 3 | P18: 4 | Q18: 5 | S18: 6 | T18: {=SUM(B40:B42*$T$7:$T$9)+$W$7} -> 1.2588938
A19: 7 | B19: 0 | C19: 0.61185768 | D19: -1.6862565 | E19: -0.39331256 | F19: 1.0273144 | G19: 1.3115002 | H19: 0 | L19: 1 | M19: {=SUM(B13:D17*$M$7:$O$11)+$M$15} -> -0.42034827 | N19: {=SUM(C13:E17*$M$7:$O$11)+$M$15} -> 2.8409404 | O19: {=SUM(D13:F17*$M$7:$O$11)+$M$15} -> 1.0094657 | P19: {=SUM(E13:G17*$M$7:$O$11)+$M$15} -> 4.0296677 | Q19: {=SUM(F13:H17*$M$7:$O$11)+$M$15} -> 0.22317045
A20: 8 | B20: 0 | C20: -0.4509497 | D20: 0.098350912 | E20: 1.3402387 | F20: 0.52920668 | G20: 0.78585619 | H20: 0 | L20: 2 | M20: {=SUM(B14:D18*$M$7:$O$11)+$M$15} -> 0.25689827 | N20: {=SUM(C14:E18*$M$7:$O$11)+$M$15} -> 3.1757752 | O20: {=SUM(D14:F18*$M$7:$O$11)+$M$15} -> 1.036264 | P20: {=SUM(E14:G18*$M$7:$O$11)+$M$15} -> 2.8218983 | Q20: {=SUM(F14:H18*$M$7:$O$11)+$M$15} -> -1.8207767 | T20: RELU | U20: Pers 2.16
A21: 9 | B21: 0 | C21: 0 | D21: 0 | E21: 0 | F21: 0 | G21: 0 | H21: 0 | L21: 3 | M21: {=SUM(B15:D19*$M$7:$O$11)+$M$15} -> -0.80936169 | N21: {=SUM(C15:E19*$M$7:$O$11)+$M$15} -> 3.1834322 | O21: {=SUM(D15:F19*$M$7:$O$11)+$M$15} -> 3.3789276 | P21: {=SUM(E15:G19*$M$7:$O$11)+$M$15} -> -0.59833113 | Q21: {=SUM(F15:H19*$M$7:$O$11)+$M$15} -> -1.6200946 | T21: 1
A22: 10 | B22: 0 | C22: 0 | D22: 0 | E22: 0 | F22: 0 | G22: 0 | H22: 0 | L22: 4 | M22: {=SUM(B16:D20*$M$7:$O$11)+$M$15} -> 1.4276994 | N22: {=SUM(C16:E20*$M$7:$O$11)+$M$15} -> 0.71676249 | O22: {=SUM(D16:F20*$M$7:$O$11)+$M$15} -> -2.9033451 | P22: {=SUM(E16:G20*$M$7:$O$11)+$M$15} -> 1.5094132 | Q22: {=SUM(F16:H20*$M$7:$O$11)+$M$15} -> -0.025170342 | S22: 1 | T22: =MAX(0,T13) -> 1.4261842
L23: 5 | M23: {=SUM(B17:D21*$M$7:$O$11)+$M$15} -> 4.5198657 | N23: {=SUM(C17:E21*$M$7:$O$11)+$M$15} -> -0.37831055 | O23: {=SUM(D17:F21*$M$7:$O$11)+$M$15} -> 0.11944987 | P23: {=SUM(E17:G21*$M$7:$O$11)+$M$15} -> -0.66688288 | Q23: {=SUM(F17:H21*$M$7:$O$11)+$M$15} -> 3.699123 | S23: 2 | T23: =MAX(0,T14) -> 0.83446165
B24: INPUT MEAN-POOLED | L24: 6 | M24: {=SUM(B18:D22*$M$7:$O$11)+$M$15} -> 0.45104667 | N24: {=SUM(C18:E22*$M$7:$O$11)+$M$15} -> 0.64449565 | O24: {=SUM(D18:F22*$M$7:$O$11)+$M$15} -> 1.2183254 | P24: {=SUM(E18:G22*$M$7:$O$11)+$M$15} -> -0.60824919 | Q24: {=SUM(F18:H22*$M$7:$O$11)+$M$15} -> 3.0540707 | S24: 3 | T24: =MAX(0,T15) -> 1.839316
B25: 1 | S25: 4 | T25: =MAX(0,T16) -> 0.40501336
A26: 1 | B26: =AVERAGE(B4:F4) -> 0.36548104 | M26: RELU | N26: Pers 2.9 | S26: 5 | T26: =MAX(0,T17) -> 0.53701995
A27: 2 | B27: =AVERAGE(B5:F5) -> -0.24318937 | M27: 1 | N27: 2 | O27: 3 | P27: 4 | Q27: 5 | S27: 6 | T27: =MAX(0,T18) -> 1.2588938
A28: 3 | B28: =AVERAGE(B6:F6) -> 0.086633902 | L28: 1 | M28: =MAX(0,M19) -> 0 | N28: =MAX(0,N19) -> 2.8409404 | O28: =MAX(0,O19) -> 1.0094657 | P28: =MAX(0,P19) -> 4.0296677 | Q28: =MAX(0,Q19) -> 0.22317045
A29: 4 | B29: =AVERAGE(B7:F7) -> -0.8436868 | L29: 2 | M29: =MAX(0,M20) -> 0.25689827 | N29: =MAX(0,N20) -> 3.1757752 | O29: =MAX(0,O20) -> 1.036264 | P29: =MAX(0,P20) -> 2.8218983 | Q29: =MAX(0,Q20) -> 0
A30: 5 | B30: =AVERAGE(B8:F8) -> 0.17422067 | L30: 3 | M30: =MAX(0,M21) -> 0 | N30: =MAX(0,N21) -> 3.1834322 | O30: =MAX(0,O21) -> 3.3789276 | P30: =MAX(0,P21) -> 0 | Q30: =MAX(0,Q21) -> 0
A31: 6 | B31: =AVERAGE(B9:F9) -> 0.46054055 | L31: 4 | M31: =MAX(0,M22) -> 1.4276994 | N31: =MAX(0,N22) -> 0.71676249 | O31: =MAX(0,O22) -> 0 | P31: =MAX(0,P22) -> 1.5094132 | Q31: =MAX(0,Q22) -> 0
L32: 5 | M32: =MAX(0,M23) -> 4.5198657 | N32: =MAX(0,N23) -> 0 | O32: =MAX(0,O23) -> 0.11944987 | P32: =MAX(0,P23) -> 0 | Q32: =MAX(0,Q23) -> 3.699123
B33: INPUT MEAN-POOLED PADDED | L33: 6 | M33: =MAX(0,M24) -> 0.45104667 | N33: =MAX(0,N24) -> 0.64449565 | O33: =MAX(0,O24) -> 1.2183254 | P33: =MAX(0,P24) -> 0 | Q33: =MAX(0,Q24) -> 3.0540707
B34: 1
A35: 1 | B35: 0
A36: 2 | B36: {=B26:B31} -> 0.36548104 | M36: MAX-POOLING | N36: Pers 2.9
A37: 3 | B37: -0.24318937 | M37: KERNEL 1x5
A38: 4 | B38: 0.086633902 | M38: 1
A39: 5 | B39: -0.8436868 | L39: 1 | M39: =MAX(M28:Q28) -> 4.0296677
A40: 6 | B40: 0.17422067 | L40: 2 | M40: =MAX(M29:Q29) -> 3.1757752
A41: 7 | B41: 0.46054055 | L41: 3 | M41: =MAX(M30:Q30) -> 3.3789276
...

Sheet CNN-BE
C2: CONCATENATE | I2: FEED-FORWARD | M2: FEED-FORWARD | U2: BACKPROPAGATION | AA2: BACKPROPAGATION
C3: 1 | D3: 2 | I3: KONVOLUSI VERTIKAL | M3: CLASSIFIER | U3: CLASSIFIER | AA3: BACK-END | AI3: 0 | AJ3: 0 | AK3: 0 | AL3: 0 | AM3: 0 | AN3: 0 | AO3: 0 | AP3: 0
B4: 1 | C4: {=FRONTEND!M49:N54} -> 4.0296677 | D4: 1.4261842 | AI4: 0 | AJ4: 0 | AK4: 0 | AL4: 0 | AM4: 0 | AN4: 0 | AO4: 0 | AP4: 0
B5: 2 | C5: 3.1757752 | D5: 0.83446165 | I5: KERNEL | M5: INPUT | P5: BOBOT | U5: L wrt y_n | V5: Pers 2.96 | AA5: KE RELU | AB5: Pers 2.25 | AI5: 0 | AJ5: 0 | AK5: 0 | AL5: 0 | AM5: 0 | AN5: 0 | AO5: 0 | AP5: 0
B6: 3 | C6: 3.3789276 | D6: 1.839316 | I6: 1 | J6: 2 | M6: 1 | P6: 1 | Q6: 2 | R6: 3 | U6: 1 | AA6: 1 | AB6: 2 | AI6: 0 | AJ6: 0 | AK6: 0 | AL6: =C4 -> 4.0296677 | AM6: =D4 -> 1.4261842 | AN6: 0 | AO6: 0 | AP6: 0
B7: 4 | C7: 1.5094132 | D7: 0.40501336 | H7: 1 | I7: -0.204 | J7: -0.74 | L7: 1 | M7: =I47 -> 3.9314647 | O7: 1 | P7: -0.134 | Q7: -0.671 | R7: -0.778 | T7: 1 | U7: =-1/3*((2/(1+DATA!$I$16))*N27/M21-((2*DATA!$I$16)/(1+DATA!$I$16))*(1-N27)*(1-M21)) -> -28.138492 | Z7: 1 | AA7: =U75*IF(U75>0,1,0) -> #VALUE! | AB7: =V75*IF(V75>0,1,0) -> #VALUE! | AI7: 0 | AJ7: 0 | AK7: 0 | AL7: =C5 -> 3.1757752 | AM7: =D5 -> 0.83446165 | AN7: 0 | AO7: 0 | AP7: 0
B8: 5 | C8: 4.5198657 | D8: 0.53701995 | H8: 2 | I8: 0.805 | J8: -0.977 | L8: 2 | M8: =I48 -> 2.5786605 | O8: 2 | P8: -0.945 | Q8: -0.04 | R8: 0.991 | T8: 2 | U8: =-1/3*((2/(1+DATA!$I$16))*N28/M22-((2*DATA!$I$16)/(1+DATA!$I$16))*(1-N28)*(1-M22)) -> 0.056701556 | Z8: 2 | AA8: =U76*IF(U76>0,1,0) -> #VALUE! | AB8: =V76*IF(V76>0,1,0) -> #VALUE! | AI8: 0 | AJ8: 0 | AK8: 0 | AL8: =C6 -> 3.3789276 | AM8: =D6 -> 1.839316 | AN8: 0 | AO8: 0 | AP8: 0
B9: 6 | C9: 3.0540707 | D9: 1.2588938 | H9: 3 | I9: 0.516 | J9: -0.914 | L9: 3 | M9: =I49 -> 2.02834 | O9: 3 | P9: -0.62 | Q9: 0.312 | R9: -0.121 | T9: 3 | U9: =-1/3*((2/(1+DATA!$I$16))*N29/M23-((2*DATA!$I$16)/(1+DATA!$I$16))*(1-N29)*(1-M23)) -> -0.91265248 | Z9: 3 | AA9: =U77*IF(U77>0,1,0) -> #VALUE! | AB9: =V77*IF(V77>0,1,0) -> #VALUE! | AI9: 0 | AJ9: 0 | AK9: 0 | AL9: =C7 -> 1.5094132 | AM9: =D7 -> 0.40501336 | AN9: 0 | AO9: 0 | AP9: 0
B10: DARI FRONT-END | L10: 4 | M10: =I50 -> 2.0931661 | O10: 4 | P10: -0.291 | Q10: -0.202 | R10: 0.186 | Z10: 4 | AA10: =U78*IF(U78>0,1,0) -> #VALUE! | AB10: =V78*IF(V78>0,1,0) -> #VALUE! | AI10: 0 | AJ10: 0 | AK10: 0 | AL10: =C8 -> 4.5198657 | AM10: =D8 -> 0.53701995 | AN10: 0 | AO10: 0 | AP10: 0
I11: BIAS | Z11: 5 | AA11: =U79*IF(U79>0,1,0) -> #VALUE! | AB11: =V79*IF(V79>0,1,0) -> #VALUE! | AI11: 0 | AJ11: 0 | AK11: 0 | AL11: =C9 -> 3.0540707 | AM11: =D9 -> 1.2588938 | AN11: 0 | AO11: 0 | AP11: 0
C12: CONCATENATE PADDING | I12: 1 | T12: Pers 2.99 | U12: KE SIGMOID | Z12: 6 | AA12: =U80*IF(U80>0,1,0) -> #VALUE! | AB12: =V80*IF(V80>0,1,0) -> #VALUE! | AI12: 0 | AJ12: 0 | AK12: 0 | AL12: 0 | AM12: 0 | AN12: 0 | AO12: 0 | AP12: 0
C13: 1 | D13: 2 | E13: 3 | H13: 1 | I13: 1 | M13: OUTPUT | N13: Pers 2.94 | P13: BIAS | U13: 1 | AI13: 0 | AJ13: 0 | AK13: 0 | AL13: 0 | AM13: 0 | AN13: 0 | AO13: 0 | AP13: 0
B14: 1 | C14: 0 | D14: 0 | E14: 0 | M14: 1 | P14: 1 | T14: 1 | U14: =-1/3*((2/(1+DATA!$I$16))*N27*(1-M21)-((2*DATA!$I$16)/(1+DATA!$I$16))*(1-N27)*M21) -> -0.58500514 | AA14: KERNEL | AB14: Pers 2.26 | AE14: BIAS | AF14: Pers 2.27 | AI14: 0 | AJ14: 0 | AK14: 0 | AL14: 0 | AM14: 0 | AN14: 0 | AO14: 0 | AP14: 0
B15: 2 | C15: =C4 -> 4.0296677 | D15: =D4 -> 1.4261842 | E15: 0 | I15: HASIL | J15: Pers 2.23 | L15: 1 | M15: {=TRANSPOSE(MMULT(TRANSPOSE(M7:M10),P7:R10)+TRANSPOSE(P15:P17))} -> -3.8303326 | O15: 1 | P15: 1 | T15: 2 | U15: =-1/3*((2/(1+DATA!$I$16))*N28*(1-M22)-((2*DATA!$I$16)/(1+DATA!$I$16))*(1-N28)*M22) -> 0.012263961 | AA15: 1 | AB15: 2 | AE15: 1 | AI15: Catatan: ini adalah matriks hasil concatenate dari front-end saat feed-forward
B16: 3 | C16: =C5 -> 3.1757752 | D16: =D5 -> 0.83446165 | E16: 0 | I16: 1 | J16: 2 | L16: 2 | M16: -1.5311367 | O16: 2 | P16: 1 | T16: 3 | U16: =-1/3*((2/(1+DATA!$I$16))*N29*(1-M23)-((2*DATA!$I$16)/(1+DATA!$I$16))*(1-N29)*M23) -> -0.20626337 | Z16: 1 | AA16: {=I7-M32*SUM($AA$7:$AB$12*AL5:AM10)} -> #VALUE! | AB16: {=J7-N32*SUM($AA$7:$AB$12*AM5:AN10)} -> #VALUE! | AD16: 1 | AE16: =I13-M32*SUM(AA7:AB12) -> #VALUE!
B17: 4 | C17: =C6 -> 3.3789276 | D17: =D6 -> 1.839316 | E17: 0 | H17: 1 | I17: {=SUM(C14:D16*$I$7:$J$9)+$I$13} -> 3.7265026 | J17: {=SUM(D14:E16*$I$7:$J$9)+$I$13} -> 2.5786605 | L17: 3 | M17: 0.64067276 | O17: 3 | P17: 1 | Z17: 2 | AA17: {=I8-M40*SUM($AA$7:$AB$12*AL6:AM11)} -> #VALUE! | AB17: {=J8-N40*SUM($AA$7:$AB$12*AM6:AN11)} -> #VALUE! | AI17: 0 | AJ17: 0 | AK17: 0 | AL17: 0 | AM17: 0 | AN17: 0 | AO17: 0 | AP17: 0 | AS17: 0 | AT17: 1
B18: 5 | C18: =C7 -> 1.5094132 | D18: =D7 -> 0.40501336 | E18: 0 | H18: 2 | I18: {=SUM(C15:D17*$I$7:$J$9)+$I$13} -> 0.92619334 | J18: {=SUM(D15:E17*$I$7:$J$9)+$I$13} -> 2.3298871 | Z18: 3 | AA18: {=I9-M41*SUM($AA$7:$AB$12*AL7:AM12)} -> #VALUE! | AB18: {=J9-N41*SUM($AA$7:$AB$12*AM7:AN12)} -> #VALUE! | AI18: 0 | AJ18: 0 | AK18: 0 | AL18: 0 | AM18: 0 | AN18: 0 | AO18: 0 | AP18: 0 | AS18: 1 | AT18: 0
B19: 6 | C19: =C8 -> 4.5198657 | D19: =D8 -> 0.53701995 | E19: 0 | H19: 3 | I19: {=SUM(C16:D18*$I$7:$J$9)+$I$13} -> 1.0663402 | J19: {=SUM(D16:E18*$I$7:$J$9)+$I$13} -> 2.5194061 | M19: OUTPUT SIGMOID | O19: Pers 2.95 | U19: BOBOT | V19: Pers 2.100 | AI19: 0 | AJ19: 0 | AK19: 0 | AL19: 0 | AM19: 0 | AN19: 0 | AO19: 0 | AP19: 0
B20: 7 | C20: =C9 -> 3.0540707 | D20: =D9 -> 1.2588938 | E20: 0 | H20: 4 | I20: {=SUM(C17:D19*$I$7:$J$9)+$I$13} -> 1.6103989 | J20: {=SUM(D17:E19*$I$7:$J$9)+$I$13} -> 1.2279176 | M20: 1 | U20: 1 | V20: 2 | W20: 3 | AA20: KE FRONT-END | AC20: Pers 2.31 | AI20: 0 | AJ20: 0 | AK20: 0 | AL20: {=AA7:AB12} -> #VALUE! | AM20: #VALUE! | AN20: 0 | AO20: 0 | AP20: 0 | AS20: 0 | AT20: 0 | AU20: 1
B21: 8 | C21: 0 | D21: 0 | E21: 0 | H21: 5 | I21: {=SUM(C18:D20*$I$7:$J$9)+$I$13} -> 3.9314647 | J21: {=SUM(D18:E20*$I$7:$J$9)+$I$13} -> 1.9992676 | L21: 1 | M21: =1/(1+EXP(-M15)) -> 0.021241407 | N21: gembira | T21: 1 | U21: {=P7:P10-$M$32*$U14*$M$7:$M$10} -> 0.095992705 | V21: {=Q7:Q10-$M$32*$U14*$M$7:$M$10} -> -0.44100729 | W21: {=R7:R10-$M$32*$U14*$M$7:$M$10} -> -0.54800729 | AA21: 1 | AB21: 2 | AI21: 0 | AJ21: 0 | AK21: 0 | AL21: #VALUE! | AM21: #VALUE! | AN21: 0 | AO21: 0 | AP21: 0 | AS21: 0 | AT21: 1 | AU21: 0
H22: 6 | I22: {=SUM(C19:D21*$I$7:$J$9)+$I$13} -> 0.90914028 | J22: {=SUM(D19:E21*$I$7:$J$9)+$I$13} -> 1.9038575 | L22: 2 | M22: =1/(1+EXP(-M16)) -> 0.17782743 | N22: sedih | T22: 2 | U22: -0.79414704 | V22: 0.11085296 | W22: 1.141853 | Z22: 1 | AA22: {=SUM(MMULT($AS$20:$AU$22,MMULT(AL19:AM21,$AS$17:$AT$18))*$AA$16:$AB$18)} -> #VALUE! | AB22: {=SUM(MMULT($AS$20:$AU$22,MMULT(AM19:AN21,$AS$17:$AT$18))*$AA$16:$AB$18)} -> #VALUE! | AI22: 0 | AJ22: 0 | AK22: 0 | AL22: #VALUE! | AM22: #VALUE! | AN22: 0 | AO22: 0 | AP22: 0 | AS22: 1 | AT22: 0 | AU22: 0
L23: 3 | M23: =1/(1+EXP(-M17)) -> 0.65490552 | N23: tegang | T23: 3 | U23: -0.50134107 | V23: 0.43065893 | W23: -0.0023410672 | Z23: 2 | AA23: {=SUM(MMULT($AS$20:$AU$22,MMULT(AL20:AM22,$AS$17:$AT$18))*$AA$16:$AB$18)} -> #VALUE! | AB23: {=SUM(MMULT($AS$20:$AU$22,MMULT(AM20:AN22,$AS$17:$AT$18))*$AA$16:$AB$18)} -> #VALUE! | AI23: 0 | AJ23: 0 | AK23: 0 | AL23: #VALUE! | AM23: #VALUE! | AN23: 0 | AO23: 0 | AP23: 0
I24: RELU | J24: Pers 2.24 | T24: 4 | U24: -0.16854871 | V24: -0.079548711 | W24: 0.30845129 | Z24: 3 | AA24: {=SUM(MMULT($AS$20:$AU$22,MMULT(AL21:AM23,$AS$17:$AT$18))*$AA$16:$AB$18)} -> #VALUE! | AB24: {=SUM(MMULT($AS$20:$AU$22,MMULT(AM21:AN23,$AS$17:$AT$18))*$AA$16:$AB$18)} -> #VALUE! | AI24: 0 | AJ24: 0 | AK24: 0 | AL24: #VALUE! | AM24: #VALUE! | AN24: 0 | AO24: 0 | AP24: 0
I25: 1 | J25: 2 | M25: LOSS | O25: Pers 2.122 | Z25: 4 | AA25: {=SUM(MMULT($AS$20:$AU$22,MMULT(AL22:AM24,$AS$17:$AT$18))*$AA$16:$AB$18)} -> #VALUE! | AB25: {=SUM(MMULT($AS$20:$AU$22,MMULT(AM22:AN24,$AS$17:$AT$18))*$AA$16:$AB$18)} -> #VALUE! | AI25: 0 | AJ25: 0 | AK25: 0 | AL25: #VALUE! | AM25: #VALUE! | AN25: 0 | AO25: 0 | AP25: 0
H26: 1 | I26: =MAX(0,I17) -> 3.7265026 | J26: =MAX(0,J17) -> 2.5786605 | M26: 1 | N26: t_n | Z26: 5 | AA26: {=SUM(MMULT($AS$20:$AU$22,MMULT(AL23:AM25,$AS$17:$AT$18))*$AA$16:$AB$18)} -> #VALUE! | AB26: {=SUM(MMULT($AS$20:$AU$22,MMULT(AM23:AN25,$AS$17:$AT$18))*$AA$16:$AB$18)} -> #VALUE! | AI26: 0 | AJ26: 0 | AK26: 0 | AL26: 0 | AM26: 0 | AN26: 0 | AO26: 0 | AP26: 0
H27: 2 | I27: =MAX(0,I18) -> 0.92619334 | J27: =MAX(0,J18) -> 2.3298871 | L27: n=1 | M27: =((2/(1+DATA!$I$16))*N27*LN(M21)+((2*DATA!$I$16)/(1+DATA!$I$16))*(1-N27)*LN(1-M21)) -> -6.906681 | N27: 1 | U27: BIAS | V27: Pers 2.101 | Z27: 6 | AA27: {=SUM(MMULT($AS$20:$AU$22,MMULT(AL24:AM26,$AS$17:$AT$18))*$AA$16:$AB$18)} -> #VALUE! | AB27: {=SUM(MMULT($AS$20:$AU$22,MMULT(AM24:AN26,$AS$17:$AT$18))*$AA$16:$AB$18)} -> #VALUE! | AI27: 0 | AJ27: 0 | AK27: 0 | AL27: 0 | AM27: 0 | AN27: 0 | AO27: 0 | AP27: 0
H28: 3 | I28: =MAX(0,I19) -> 1.0663402 | J28: =MAX(0,J19) -> 2.5194061 | L28: 2 | M28: =((2/(1+DATA!$I$17))*N28*LN(M22)+((2*DATA!$I$17)/(1+DATA!$I$17))*(1-N28)*LN(1-M22)) -> -0.14918474 | N28: 0 | U28: 1 | AI28: 0 | AJ28: 0 | AK28: 0 | AL28: 0 | AM28: 0 | AN28: 0 | AO28: 0 | AP28: 0
H29: 4 | I29: =MAX(0,I20) -> 1.6103989 | J29: =MAX(0,J20) -> 1.2279176 | L29: 3 | M29: =((2/(1+DATA!$I$18))*N29*LN(M23)+((2*DATA!$I$18)/(1+DATA!$I$18))*(1-N29)*LN(1-M23)) -> -0.66696192 | N29: 1 | T29: 1 | U29: =P15-$M$32*$U14 -> 1.0585005 | AI29: Catatan: matriks gradien RELU di-flip vertikal lalu horizontal sebelum dikalikan dengan kernel
H30: 5 | I30: =MAX(0,I21) -> 3.9314647 | J30: =MAX(0,J21) -> 1.9992676 | L30: avg | M30: =-1*SUM(M27:M29)/3 -> 2.5742759 | T30: 2 | U30: =P16-$M$32*$U15 -> 0.9987736
H31: 6 | I31: =MAX(0,I22) -> 0.90914028 | J31: =MAX(0,J22) -> 1.9038575 | T31: 3 | U31: =P17-$M$32*$U16 -> 1.0206263
L32: lr= | M32: 0.1 | AA32: FRONT-END
I33: MAX-POOLING | AA33: KONVOLUSI VERTIKAL
I34: KERNEL 1x2 | J34: Pers 2.92 | AA34: KE MAX-POOLING | AC34: HASIL | AD34: Pers 2.10 | AI34: 0 | AJ34: 0 | AK34: 0 | AL34: 0 | AM34: 0 | AN34: 0 | AO34: 0 | AP34: 0 | AQ34: 0 | AR34: 0 | AS34: 0
I35: 1 | J35: 2 | AA35: 1 | AB35: argmax | AC35: 1 | AD35: 2 | AE35: 3 | AF35: 4 | AG35: 5 | AI35: 0 | AJ35: 0 | AK35: 0 | AL35: 0 | AM35: 0 | AN35: 0 | AO35: 0 | AP35: 0 | AQ35: 0 | AR35: 0 | AS35: 0
H36: 1 | I36: =MAX(I26:I31) -> 3.9314647 | J36: =MAX(J26:J31) -> 2.5786605 | Z36: 1 | AA36: =AA22 -> #VALUE! | AB36: =MATCH(MAX(FRONTEND!M28:Q28),FRONTEND!M28:Q28,0) -> 4 | AC36: =IF($AB36=AC$35,$AA36,0) -> 0 | AD36: =IF($AB36=AD$35,$AA36,0) -> 0 | AE36: =IF($AB36=AE$35,$AA36,0) -> 0 | AF36: =IF($AB36=AF$35,$AA36,0) -> #VALUE! | AG36: =IF($AB36=AG$35,$AA36,0) -> 0 | AI36: 0 | AJ36: 0 | AK36: 0 | AL36: 0 | AM36: 0 | AN36: 0 | AO36: 0 | AP36: 0 | AQ36: 0 | AR36: 0 | AS36: 0
Z37: 2 | AA37: =AA23 -> #VALUE! | AB37: =MATCH(MAX(FRONTEND!M29:Q29),FRONTEND!M29:Q29,0) -> 2 | AC37: =IF($AB37=AC$35,$AA37,0) -> 0 | AD37: =IF($AB37=AD$35,$AA37,0) -> #VALUE! | AE37: =IF($AB37=AE$35,$AA37,0) -> 0 | AF37: =IF($AB37=AF$35,$AA37,0) -> 0 | AG37: =IF($AB37=AG$35,$AA37,0) -> 0 | AI37: 0 | AJ37: 0 | AK37: 0 | AL37: {=FRONTEND!B4:F9} -> 0.098070128 | AM37: 0.76989837 | AN37: 1.0888675 | AO37: 0.41864133 | AP37: -0.54807215 | AQ37: 0 | AR37: 0 | AS37: 0
Z38: 3 | AA38: =AA24 -> #VALUE! | AB38: =MATCH(MAX(FRONTEND!M30:Q30),FRONTEND!M30:Q30,0) -> 3 | AC38: =IF($AB38=AC$35,$AA38,0) -> 0 | AD38: =IF($AB38=AD$35,$AA38,0) -> 0 | AE38: =IF($AB38=AE$35,$AA38,0) -> #VALUE! | AF38: =IF($AB38=AF$35,$AA38,0) -> 0 | AG38: =IF($AB38=AG$35,$AA38,0) -> 0 | AI38: 0 | AJ38: 0 | AK38: 0 | AL38: 0.39479458 | AM38: 0.76298403 | AN38: -1.5092547 | AO38: 0.78695236 | AP38: -1.6514231 | AQ38: 0 | AR38: 0 | AS38: 0
I39: MEAN-POOLING | Z39: 4 | AA39: =AA25 -> #VALUE! | AB39: =MATCH(MAX(FRONTEND!M31:Q31),FRONTEND!M31:Q31,0) -> 4 | AC39: =IF($AB39=AC$35,$AA39,0) -> 0 | AD39: =IF($AB39=AD$35,$AA39,0) -> 0 | AE39: =IF($AB39=AE$35,$AA39,0) -> 0 | AF39: =IF($AB39=AF$35,$AA39,0) -> #VALUE! | AG39: =IF($AB39=AG$35,$AA39,0) -> 0 | AI39: 0 | AJ39: 0 | AK39: 0 | AL39: 1.2610502 | AM39: 1.0201002 | AN39: 0.20946803 | AO39: -1.5474479 | AP39: -0.51000095 | AQ39: 0 | AR39: 0 | AS39: 0
I40: KERNEL 1x2 | J40: Pers 2.92 | U40: KE POOLING | Z40: 5 | AA40: =AA26 -> #VALUE! | AB40: =MATCH(MAX(FRONTEND!M32:Q32),FRONTEND!M32:Q32,0) -> 1 | AC40: =IF($AB40=AC$35,$AA40,0) -> #VALUE! | AD40: =IF($AB40=AD$35,$AA40,0) -> 0 | AE40: =IF($AB40=AE$35,$AA40,0) -> 0 | AF40: =IF($AB40=AF$35,$AA40,0) -> 0 | AG40: =IF($AB40=AG$35,$AA40,0) -> 0 | AI40: 0 | AJ40: 0 | AK40: 0 | AL40: -1.9148228 | AM40: -0.96507706 | AN40: -0.73600695 | AO40: -1.2146669 | AP40: 0.61213976 | AQ40: 0 | AR40: 0 | AS40: 0
I41: 1 | J41: 2 | U41: 1 | V41: Pers 2.102 | Z41: 6 | AA41: =AA27 -> #VALUE! | AB41: =MATCH(MAX(FRONTEND!M33:Q33),FRONTEND!M33:Q33,0) -> 5 | AC41: =IF($AB41=AC$35,$AA41,0) -> 0 | AD41: =IF($AB41=AD$35,$AA41,0) -> 0 | AE41: =IF($AB41=AE$35,$AA41,0) -> 0 | AF41: =IF($AB41=AF$35,$AA41,0) -> 0 | AG41: =IF($AB41=AG$35,$AA41,0) -> #VALUE! | AI41: 0 | AJ41: 0 | AK41: 0 | AL41: 0.61185768 | AM41: -1.6862565 | AN41: -0.39331256 | AO41: 1.0273144 | AP41: 1.3115002 | AQ41: 0 | AR41: 0 | AS41: 0
...

Sheet GRU-BE
C2: CONCATENATE | L2: FEED-FORWARD | W2: FEED-FORWARD | AE2: BACKPROPAGATION | AK2: BACKPROPAGATION | BL2: FRONT-END
C3: 1 | D3: 2 | L3: GRU | W3: CLASSIFIER | AE3: CLASSIFIER | AK3: GRU | BL3: KONVOLUSI VERTIKAL
B4: 1 | C4: {=FRONTEND!M49:N54} -> 4.0296677 | D4: 1.4261842 | K4: F_out x 1 | BL4: KE MAX-POOLING | BN4: HASIL | BO4: Pers 2.10 | BT4: 0 | BU4: 0 | BV4: 0 | BW4: 0 | BX4: 0 | BY4: 0 | BZ4: 0 | CA4: 0 | CB4: 0 | CC4: 0 | CD4: 0
B5: 2 | C5: 3.1757752 | D5: 0.83446165 | L5: h_0 | N5: F_in | O5: 2 | P5: (banyak fitur pada masukan) | W5: INPUT | Z5: BOBOT | AE5: L wrt y_n | AF5: Pers 2.96 | AK5: t=6 | AM5: Pers 2.43 | AN5: Pers 2.44 | AO5: Pers 2.45 | AP5: Pers 2.46 | AQ5: Pers 2.47 | AR5: Pers 2.48 | AS5: Pers 2.49 | AU5: t=6 | AY5: Pers 2.52 | BD5: Pers 2.55 | BI5: Pers 2.58 | BL5: 1 | BM5: argmax | BN5: 1 | BO5: 2 | BP5: 3 | BQ5: 4 | BR5: 5 | BT5: 0 | BU5: 0 | BV5: 0 | BW5: 0 | BX5: 0 | BY5: 0 | BZ5: 0 | CA5: 0 | CB5: 0 | CC5: 0 | CD5: 0
B6: 3 | C6: 3.3789276 | D6: 1.839316 | L6: 1 | N6: F_out | O6: 2 | P6: (banyak fitur pada hidden state dan keluaran) | W6: 1 | Z6: 1 | AA6: 2 | AB6: 3 | AE6: 1 | AJ6: Pers 2.39 | AK6: L wrt h_t | AM6: L wrt ~h_t | AN6: L wrt z_~h(t) | AO6: L wrt z_t | AP6: L wrt z_z(t) | AQ6: L wrt r_t | AR6: L wrt z_r(t) | AS6: L wrt h_t-1 | AU6: L wrt W_h | AV6: Pers 2.50 | AW6: L wrt U_h | AX6: Pers 2.51 | AY6: L wrt b_h | AZ6: L wrt W_z | BA6: Pers 2.53 | BB6: L wrt U_z | BC6: Pers 2.54 | BD6: L wrt b_z | BE6: L wrt W_r | BF6: Pers 2.56 | BG6: L wrt U_r | BH6: Pers 2.57 | BI6: L wrt b_r | BK6: 1 | BL6: {=AU56:AU61} -> 0.050890063 | BM6: =MATCH(MAX(FRONTEND!$M28:$Q28),FRONTEND!$M28:$Q28,0) -> 4 | BN6: =IF($BM6=BN$5,$BL6,0) -> 0 | BO6: =IF($BM6=BO$5,$BL6,0) -> 0 | BP6: =IF($BM6=BP$5,$BL6,0) -> 0 | BQ6: =IF($BM6=BQ$5,$BL6,0) -> 0.050890063 | BR6: =IF($BM6=BR$5,$BL6,0) -> 0 | BT6: 0 | BU6: 0 | BV6: 0 | BW6: 0 | BX6: 0 | BY6: 0 | BZ6: 0 | CA6: 0 | CB6: 0 | CC6: 0 | CD6: 0
B7: 4 | C7: 1.5094132 | D7: 0.40501336 | K7: 1 | L7: 0.805 | V7: 1 | W7: =K74 -> 0.6085699 | Y7: 1 | Z7: -0.134 | AA7: -0.671 | AB7: -0.778 | AD7: 1 | AE7: =-1/3*((2/(1+DATA!$I$16))*X34/W28-((2*DATA!$I$16)/(1+DATA!$I$16))*(1-X34)*(1-W28)) -> -1.3425747 | AK7: 1 | AM7: 1 | AN7: 1 | AO7: 1 | AP7: 1 | AQ7: 1 | AR7: 1 | AS7: 1 | AU7: 1 | AV7: 2 | AW7: 1 | AX7: 2 | AY7: 1 | AZ7: 1 | BA7: 2 | BB7: 1 | BC7: 2 | BD7: 1 | BE7: 1 | BF7: 2 | BG7: 1 | BH7: 2 | BI7: 1 | BK7: 2 | BL7: 0.040980476 | BM7: =MATCH(MAX(FRONTEND!$M29:$Q29),FRONTEND!$M29:$Q29,0) -> 2 | BN7: =IF($BM7=BN$5,$BL7,0) -> 0 | BO7: =IF($BM7=BO$5,$BL7,0) -> 0.040980476 | BP7: =IF($BM7=BP$5,$BL7,0) -> 0 | BQ7: =IF($BM7=BQ$5,$BL7,0) -> 0 | BR7: =IF($BM7=BR$5,$BL7,0) -> 0 | BT7: 0 | BU7: 0 | BV7: 0 | BW7: {=FRONTEND!$B$4:$F$9} -> 0.098070128 | BX7: 0.76989837 | BY7: 1.0888675 | BZ7: 0.41864133 | CA7: -0.54807215 | CB7: 0 | CC7: 0 | CD7: 0
B8: 5 | C8: 4.5198657 | D8: 0.53701995 | K8: 2 | L8: -0.977 | V8: 2 | W8: =K75 -> 0.94880195 | Y8: 2 | Z8: -0.945 | AA8: -0.04 | AB8: 0.991 | AD8: 2 | AE8: =-1/3*((2/(1+DATA!$I$16))*X35/W29-((2*DATA!$I$16)/(1+DATA!$I$16))*(1-X35)*(1-W29)) -> 0.017385606 | AJ8: 1 | AK8: {=AE94:AE95} -> 0.01591847 | AM8: {=_xlfn.ANCHORARRAY(AK8)*(1-$O$59:$O$60)} -> 0.0054090946 | AN8: {=_xlfn.ANCHORARRAY(AM8)*(1-$R$59:$R$60*$R$59:$R$60)} -> 0.0053470125 | AO8: {=_xlfn.ANCHORARRAY(AK8)*(_xlfn.ANCHORARRAY(T53)-$R$59:$R$60)} -> -0.006383776 | AP8: {=_xlfn.ANCHORARRAY(AO8)*($O$59:$O$60*(1-$O$59:$O$60))} -> -0.0014321103 | AQ8: {=MMULT(TRANSPOSE($P$23:$Q$24),_xlfn.ANCHORARRAY($AN$8))*_xlfn.ANCHORARRAY($T$53)} -> -0.0018919813 | AR8: {=_xlfn.ANCHORARRAY($AQ$8)*($L$59:$L$60*(1-$L$59:$L$60))} -> -0.00023583815 | AS8: {=_xlfn.ANCHORARRAY(AK8)*$O$59:$O$60+MMULT(TRANSPOSE($P$23:$Q$24),_xlfn.ANCHORARRAY(AN8))*$L$59:$L$60+MMULT(TRANSPOSE($P$18:$Q$19),_xlfn.ANCHORARRAY(AP8))+MMULT(TRANSPOSE($P$13:$Q$14),_xlfn.ANCHORARRAY(AR8))} -> 0.013695299 | AU8: {=MMULT(_xlfn.ANCHORARRAY(AN8),TRANSPOSE($H$14:$H$15))} -> 0.016330154 | AV8: 0.0067313211 | AW8: {=MMULT(_xlfn.ANCHORARRAY(AN8),TRANSPOSE($L$59:$L$60*_xlfn.ANCHORARRAY($T$53)))} -> -0.0023205696 | AX8: 0.0044077715 | AY8: {=_xlfn.ANCHORARRAY(AN8)} -> 0.0053470125 | AZ8: {=MMULT(_xlfn.ANCHORARRAY(AP8),TRANSPOSE(H14:H15))} -> -0.0043737662 | BA8: -0.0018028749 | BB8: {=MMULT(_xlfn.ANCHORARRAY(AP8),TRANSPOSE(_xlfn.ANCHORARRAY($T$53)))} -> 0.00072774396 | BC8: -0.0014261308 | BD8: {=_xlfn.ANCHORARRAY(AP8)} -> -0.0014321103 | BE8: {=MMULT(_xlfn.ANCHORARRAY(AR8),TRANSPOSE($H$14:$H$15))} -> -0.00072026638 | BF8: -0.00029689519 | BG8: {=MMULT(_xlfn.ANCHORARRAY(AR8),TRANSPOSE(_xlfn.ANCHORARRAY($T$53)))} -> 0.00011984397 | BH8: -0.00023485345 | BI8: {=_xlfn.ANCHORARRAY(AR8)} -> -0.00023583815 | BK8: 3 | BL8: 0.026940478 | BM8: =MATCH(MAX(FRONTEND!$M30:$Q30),FRONTEND!$M30:$Q30,0) -> 3 | BN8: =IF($BM8=BN$5,$BL8,0) -> 0 | BO8: =IF($BM8=BO$5,$BL8,0) -> 0 | BP8: =IF($BM8=BP$5,$BL8,0) -> 0.026940478 | BQ8: =IF($BM8=BQ$5,$BL8,0) -> 0 | BR8: =IF($BM8=BR$5,$BL8,0) -> 0 | BT8: 0 | BU8: 0 | BV8: 0 | BW8: 0.39479458 | BX8: 0.76298403 | BY8: -1.5092547 | BZ8: 0.78695236 | CA8: -1.6514231 | CB8: 0 | CC8: 0 | CD8: 0
B9: 6 | C9: 3.0540707 | D9: 1.2588938 | V9: 3 | W9: =K76 -> 0.99745141 | Y9: 3 | Z9: -0.62 | AA9: 0.312 | AB9: -0.121 | AD9: 3 | AE9: =-1/3*((2/(1+DATA!$I$16))*X36/W30-((2*DATA!$I$16)/(1+DATA!$I$16))*(1-X36)*(1-W30)) -> -0.68263746 | AJ9: 2 | AK9: -0.18405016 | AM9: -0.16949692 | AN9: -0.00025639708 | AO9: 0.00062920889 | AP9: 4.5818824e-05 | AQ9: 0.0037180971 | AR9: 0.00053000624 | AS9: -0.012559587 | AU9: -0.00078305483 | AV9: -0.00032277671 | AW9: 0.00011127471 | AX9: -0.0002113591 | AY9: -0.00025639708 | AZ9: 0.00013993393 | BA9: 5.7681036e-05 | BB9: -2.3283382e-05 | BC9: 4.5627516e-05 | BD9: 4.5818824e-05 | BE9: 0.0016186765 | BF9: 0.00066722159 | BG9: -0.00026932899 | BH9: 0.00052779329 | BI9: 0.00053000624 | BK9: 4 | BL9: 0.011866864 | BM9: =MATCH(MAX(FRONTEND!$M31:$Q31),FRONTEND!$M31:$Q31,0) -> 4 | BN9: =IF($BM9=BN$5,$BL9,0) -> 0 | BO9: =IF($BM9=BO$5,$BL9,0) -> 0 | BP9: =IF($BM9=BP$5,$BL9,0) -> 0 | BQ9: =IF($BM9=BQ$5,$BL9,0) -> 0.011866864 | BR9: =IF($BM9=BR$5,$BL9,0) -> 0 | BT9: 0 | BU9: 0 | BV9: 0 | BW9: 1.2610502 | BX9: 1.0201002 | BY9: 0.20946803 | BZ9: -1.5474479 | CA9: -0.51000095 | CB9: 0 | CC9: 0 | CD9: 0
B10: DARI FRONT-END | K10: F_out x F_in | O10: F_out x F_out | S10: F_out x 1 | V10: 4 | W10: =K77 -> 0.97148877 | Y10: 4 | Z10: -0.291 | AA10: -0.202 | AB10: 0.186 | BK10: 5 | BL10: 0.0010550625 | BM10: =MATCH(MAX(FRONTEND!$M32:$Q32),FRONTEND!$M32:$Q32,0) -> 1 | BN10: =IF($BM10=BN$5,$BL10,0) -> 0.0010550625 | BO10: =IF($BM10=BO$5,$BL10,0) -> 0 | BP10: =IF($BM10=BP$5,$BL10,0) -> 0 | BQ10: =IF($BM10=BQ$5,$BL10,0) -> 0 | BR10: =IF($BM10=BR$5,$BL10,0) -> 0 | BT10: 0 | BU10: 0 | BV10: 0 | BW10: -1.9148228 | BX10: -0.96507706 | BY10: -0.73600695 | BZ10: -1.2146669 | CA10: 0.61213976 | CB10: 0 | CC10: 0 | CD10: 0
L11: W_r | P11: U_r | T11: b_r | V11: 5 | W11: =K78 -> 0.99582468 | Y11: 5 | Z11: -0.577 | AA11: -0.185 | AB11: 0.173 | AK11: t=5 | AU11: t=5 | BK11: 6 | BL11: -0.0026878433 | BM11: =MATCH(MAX(FRONTEND!$M33:$Q33),FRONTEND!$M33:$Q33,0) -> 5 | BN11: =IF($BM11=BN$5,$BL11,0) -> 0 | BO11: =IF($BM11=BO$5,$BL11,0) -> 0 | BP11: =IF($BM11=BP$5,$BL11,0) -> 0 | BQ11: =IF($BM11=BQ$5,$BL11,0) -> 0 | BR11: =IF($BM11=BR$5,$BL11,0) -> -0.0026878433 | BT11: 0 | BU11: 0 | BV11: 0 | BW11: 0.61185768 | BX11: -1.6862565 | BY11: -0.39331256 | BZ11: 1.0273144 | CA11: 1.3115002 | CB11: 0 | CC11: 0 | CD11: 0
C12: TRANSPOSE | L12: 1 | M12: 2 | P12: 1 | Q12: 2 | T12: 1 | V12: 6 | W12: =K79 -> 0.99897304 | Y12: 6 | Z12: 0.572 | AA12: 0.892 | AB12: 0.757 | AD12: Pers 2.99 | AE12: KE SIGMOID | AJ12: Pers 2.39 | AK12: L wrt h_t | AM12: L wrt ~h_t | AN12: L wrt z_~h(t) | AO12: L wrt z_t | AP12: L wrt z_z(t) | AQ12: L wrt r_t | AR12: L wrt z_r(t) | AS12: L wrt h_t-1 | AU12: L wrt W_h | AW12: L wrt U_h | AY12: L wrt b_h | AZ12: L wrt W_z | BB12: L wrt U_z | BD12: L wrt b_z | BE12: L wrt W_r | BG12: L wrt U_r | BI12: L wrt b_r | BT12: 0 | BU12: 0 | BV12: 0 | BW12: -0.4509497 | BX12: 0.098350912 | BY12: 1.3402387 | BZ12: 0.52920668 | CA12: 0.78585619 | CB12: 0 | CC12: 0 | CD12: 0
C13: t=1 | D13: 2 | E13: 3 | F13: 4 | G13: 5 | H13: 6 | K13: 1 | L13: 0.878 | M13: -0.139 | O13: 1 | P13: -0.253 | Q13: -0.872 | S13: 1 | T13: 0 | V13: 7 | W13: =K80 -> 0.11625096 | Y13: 7 | Z13: -0.21 | AA13: -0.863 | AB13: 0.252 | AE13: 1 | AK13: 1 | AM13: 1 | AN13: 1 | AO13: 1 | AP13: 1 | AQ13: 1 | AR13: 1 | AS13: 1 | AU13: 1 | AV13: 2 | AW13: 1 | AX13: 2 | AY13: 1 | AZ13: 1 | BA13: 2 | BB13: 1 | BC13: 2 | BD13: 1 | BE13: 1 | BF13: 2 | BG13: 1 | BH13: 2 | BI13: 1 | BL13: KE RELU | BM13: Pers 2.11 | BT13: 0 | BU13: 0 | BV13: 0 | BW13: 0 | BX13: 0 | BY13: 0 | BZ13: 0 | CA13: 0 | CB13: 0 | CC13: 0 | CD13: 0
B14: 1 | C14: {=TRANSPOSE(_xlfn.ANCHORARRAY(C4))} -> 4.0296677 | D14: 3.1757752 | E14: 3.3789276 | F14: 1.5094132 | G14: 4.5198657 | H14: 3.0540707 | K14: 2 | L14: -0.013 | M14: 0.997 | O14: 2 | P14: -0.212 | Q14: 0.248 | S14: 2 | T14: 0 | V14: 8 | W14: =K81 -> 0.2244577 | Y14: 8 | Z14: 0.549 | AA14: 0.185 | AB14: -0.508 | AD14: 1 | AE14: =-1/3*((2/(1+DATA!$I$16))*X34*(1-W28)-((2*DATA!$I$16)/(1+DATA!$I$16))*(1-X34)*W28) -> -0.33161043 | AJ14: 1 | AK14: {=AF94:AF95+_xlfn.ANCHORARRAY(AS8)} -> -0.013506735 | AM14: {=_xlfn.ANCHORARRAY(AK14)*(1-$O$53:$O$54)} -> -0.0062618287 | AN14: {=_xlfn.ANCHORARRAY(AM14)*(1-$R$53:$R$54*$R$53:$R$54)} -> -0.0012689438 | AO14: {=_xlfn.ANCHORARRAY(AK14)*(_xlfn.ANCHORARRAY(T53)-$R$53:$R$54)} -> -0.0051971761 | AP14: {=_xlfn.ANCHORARRAY(AO14)*($O$53:$O$54*(1-$O$53:$O$54))} -> -0.001292411 | AQ14: {=MMULT(TRANSPOSE($P$23:$Q$24),_xlfn.ANCHORARRAY(AN14))*_xlfn.ANCHORARRAY(T47)} -> 0.000160515 | AR14: {=_xlfn.ANCHORARRAY(AQ14)*($L$53:$L$54*(1-$L$53:$L$54))} -> 6.6752385e-06 | AS14: {=_xlfn.ANCHORARRAY(AK14)*$O$53:$O$54+MMULT(TRANSPOSE($P$23:$Q$24),_xlfn.ANCHORARRAY(AN14))*$L$53:$L$54+MMULT(TRANSPOSE($P$18:$Q$19),_xlfn.ANCHORARRAY(AP14))+MMULT(TRANSPOSE($P$13:$Q$14),_xlfn.ANCHORARRAY(AR14))} -> -0.0081135459 | AU14: {=MMULT(_xlfn.ANCHORARRAY(AN14),TRANSPOSE($G$14:$G$15))} -> -0.0057354555 | AV14: -0.00068144813 | AW14: {=MMULT(_xlfn.ANCHORARRAY(AN14),TRANSPOSE($L$53:$L$54*_xlfn.ANCHORARRAY(T47)))} -> 0.00021312679 | AX14: -0.00083855704 | AY14: {=_xlfn.ANCHORARRAY(AN14)} -> -0.0012689438 | AZ14: {=MMULT(_xlfn.ANCHORARRAY(AP14),TRANSPOSE($G$14:$G$15))} -> -0.0058415239 | BA14: -0.00069405047 | BB14: {=MMULT(_xlfn.ANCHORARRAY(AP14),TRANSPOSE(_xlfn.ANCHORARRAY(T47)))} -> 0.00022693458 | BC14: -0.0012555627 | BD14: {=_xlfn.ANCHORARRAY(AP14)} -> -0.001292411 | BE14: {=MMULT(_xlfn.ANCHORARRAY(AR14),TRANSPOSE($G$14:$G$15))} -> 3.0171181e-05 | BF14: 3.5847362e-06 | BG14: {=MMULT(_xlfn.ANCHORARRAY(AR14),TRANSPOSE(_xlfn.ANCHORARRAY(T47)))} -> -1.1721059e-06 | BH14: 6.4849192e-06 | BI14: {=_xlfn.ANCHORARRAY(AR14)} -> 6.6752385e-06 | BL14: 1 | BM14: 2 | BN14: 3 | BO14: 4 | BP14: 5 | BT14: 0 | BU14: 0 | BV14: 0 | BW14: 0 | BX14: 0 | BY14: 0 | BZ14: 0 | CA14: 0 | CB14: 0 | CC14: 0 | CD14: 0
B15: 2 | C15: 1.4261842 | D15: 0.83446165 | E15: 1.839316 | F15: 0.40501336 | G15: 0.53701995 | H15: 1.2588938 | V15: 9 | W15: =K82 -> 0.37423137 | Y15: 9 | Z15: 0.99 | AA15: -0.947 | AB15: -0.905 | AD15: 2 | AE15: =-1/3*((2/(1+DATA!$I$16))*X35*(1-W29)-((2*DATA!$I$16)/(1+DATA!$I$16))*(1-X35)*W29) -> 0.051579912 | AJ15: 2 | AK15: 0.12916961 | AM15: 0.11237835 | AN15: 0.00012113564 | AO15: -0.00046968737 | AP15: -5.3119531e-05 | AQ15: -0.000808624 | AR15: -0.00017589111 | AS15: 0.014894484 | AU15: 0.00054751683 | AV15: 6.5052256e-05 | AW15: -2.0345464e-05 | AX15: 8.0050154e-05 | AY15: 0.00012113564 | AZ15: -0.00024009314 | BA15: -2.8526248e-05 | BB15: 9.3272643e-06 | BC15: -5.1605027e-05 | BD15: -5.3119531e-05 | BE15: -0.00079500419 | BF15: -9.4457036e-05 | BG15: 3.088474e-05 | BH15: -0.00017087624 | BI15: -0.00017589111 | BK15: 1 | BL15: =BN6*IF(BN6>0,1,0) -> 0 | BM15: =BO6*IF(BO6>0,1,0) -> 0 | BN15: =BP6*IF(BP6>0,1,0) -> 0 | BO15: =BQ6*IF(BQ6>0,1,0) -> 0.050890063 | BP15: =BR6*IF(BR6>0,1,0) -> 0 | BT15: 0 | BU15: 0 | BV15: 0 | BW15: 0 | BX15: 0 | BY15: 0 | BZ15: 0 | CA15: 0 | CB15: 0 | CC15: 0 | CD15: 0
L16: W_z | P16: U_z | T16: b_z | V16: 10 | W16: =K83 -> 0.39794933 | Y16: 10 | Z16: 0.469 | AA16: 0.365 | AB16: -0.207 | AD16: 3 | AE16: =-1/3*((2/(1+DATA!$I$16))*X36*(1-W30)-((2*DATA!$I$16)/(1+DATA!$I$16))*(1-X36)*W30) -> -0.074368219 | BK16: 2 | BL16: =BN7*IF(BN7>0,1,0) -> 0 | BM16: =BO7*IF(BO7>0,1,0) -> 0.040980476 | BN16: =BP7*IF(BP7>0,1,0) -> 0 | BO16: =BQ7*IF(BQ7>0,1,0) -> 0 | BP16: =BR7*IF(BR7>0,1,0) -> 0
L17: 1 | M17: 2 | P17: 1 | Q17: 2 | T17: 1 | V17: 11 | W17: =K84 -> 0.24383137 | Y17: 11 | Z17: 0.241 | AA17: 0.486 | AB17: -0.006 | AK17: t=4 | AU17: t=4 | BK17: 3 | BL17: =BN8*IF(BN8>0,1,0) -> 0 | BM17: =BO8*IF(BO8>0,1,0) -> 0 | BN17: =BP8*IF(BP8>0,1,0) -> 0.026940478 | BO17: =BQ8*IF(BQ8>0,1,0) -> 0 | BP17: =BR8*IF(BR8>0,1,0) -> 0
K18: 1 | L18: -0.212 | M18: 0.248 | O18: 1 | P18: -0.013 | Q18: 0.997 | S18: 1 | T18: 0 | V18: 12 | W18: =K85 -> 0.31354045 | Y18: 12 | Z18: -0.167 | AA18: -0.442 | AB18: 0.01 | AJ18: Pers 2.39 | AK18: L wrt h_t | AM18: L wrt ~h_t | AN18: L wrt z_~h(t) | AO18: L wrt z_t | AP18: L wrt z_z(t) | AQ18: L wrt r_t | AR18: L wrt z_r(t) | AS18: L wrt h_t-1 | AU18: L wrt W_h | AW18: L wrt U_h | AY18: L wrt b_h | AZ18: L wrt W_z | BB18: L wrt U_z | BD18: L wrt b_z | BE18: L wrt W_r | BG18: L wrt U_r | BI18: L wrt b_r | BK18: 4 | BL18: =BN9*IF(BN9>0,1,0) -> 0 | BM18: =BO9*IF(BO9>0,1,0) -> 0 | BN18: =BP9*IF(BP9>0,1,0) -> 0 | BO18: =BQ9*IF(BQ9>0,1,0) -> 0.011866864 | BP18: =BR9*IF(BR9>0,1,0) -> 0
K19: 2 | L19: -0.253 | M19: -0.872 | O19: 2 | P19: 0.878 | Q19: -0.139 | S19: 2 | T19: 0 | AE19: BOBOT | AF19: Pers 2.100 | AK19: 1 | AM19: 1 | AN19: 1 | AO19: 1 | AP19: 1 | AQ19: 1 | AR19: 1 | AS19: 1 | AU19: 1 | AV19: 2 | AW19: 1 | AX19: 2 | AY19: 1 | AZ19: 1 | BA19: 2 | BB19: 1 | BC19: 2 | BD19: 1 | BE19: 1 | BF19: 2 | BG19: 1 | BH19: 2 | BI19: 1 | BK19: 5 | BL19: =BN10*IF(BN10>0,1,0) -> 0.0010550625 | BM19: =BO10*IF(BO10>0,1,0) -> 0 | BN19: =BP10*IF(BP10>0,1,0) -> 0 | BO19: =BQ10*IF(BQ10>0,1,0) -> 0 | BP19: =BR10*IF(BR10>0,1,0) -> 0
W20: OUTPUT | X20: Pers 2.94 | Z20: BIAS | AE20: 1 | AF20: 2 | AG20: 3 | AJ20: 1 | AK20: {=AG94:AG95+_xlfn.ANCHORARRAY(AS14)} -> -0.068765748 | AM20: {=_xlfn.ANCHORARRAY(AK20)*(1-$O$47:$O$48)} -> -0.021641964 | AN20: {=_xlfn.ANCHORARRAY(AM20)*(1-$R$47:$R$48*$R$47:$R$48)} -> -0.021636582 | AO20: {=_xlfn.ANCHORARRAY(AK20)*(_xlfn.ANCHORARRAY(T41)-$R$47:$R$48)} -> 0.016037447 | AP20: {=_xlfn.ANCHORARRAY(AO20)*($O$47:$O$48*(1-$O$47:$O$48))} -> 0.0034588181 | AQ20: {=MMULT(TRANSPOSE($P$23:$Q$24),_xlfn.ANCHORARRAY(AN20))*_xlfn.ANCHORARRAY(T47)} -> 0.0026820462 | AR20: {=_xlfn.ANCHORARRAY(AQ20)*($L$47:$L$48*(1-$L$47:$L$48))} -> 0.00063594113 | AS20: {=_xlfn.ANCHORARRAY(AK20)*$O$47:$O$48+MMULT(TRANSPOSE($P$23:$Q$24),_xlfn.ANCHORARRAY(AN20))*$L$47:$L$48+MMULT(TRANSPOSE($P$18:$Q$19),_xlfn.ANCHORARRAY(AP20))+MMULT(TRANSPOSE($P$13:$Q$14),_xlfn.ANCHORARRAY(AR20))} -> -0.055872686 | AU20: {=MMULT(_xlfn.ANCHORARRAY(AN20),TRANSPOSE($F$14:$F$15))} -> -0.032658542 | AV20: -0.0087631047 | AW20: {=MMULT(_xlfn.ANCHORARRAY(AN20),TRANSPOSE($L$47:$L$48*_xlfn.ANCHORARRAY($T$41)))} -> 0.0033052602 | AX20: -0.014345276 | AY20: {=_xlfn.ANCHORARRAY(AN20)} -> -0.021636582 | AZ20: {=MMULT(_xlfn.ANCHORARRAY(AP20),TRANSPOSE($F$14:$F$15))} -> 0.0052207857 | BA20: 0.0014008675 | BB20: {=MMULT(_xlfn.ANCHORARRAY(AP20),TRANSPOSE(_xlfn.ANCHORARRAY(T47)))} -> -0.00060733426 | BC20: 0.003360203 | BD20: {=_xlfn.ANCHORARRAY(AP20)} -> 0.0034588181 | BE20: {=MMULT(_xlfn.ANCHORARRAY(AR20),TRANSPOSE($F$14:$F$15))} -> 0.00095989792 | BF20: 0.00025756465 | BG20: {=MMULT(_xlfn.ANCHORARRAY(AR20),TRANSPOSE(_xlfn.ANCHORARRAY(T41)))} -> -0.00015834214 | BH20: 0.00063432037 | BI20: {=_xlfn.ANCHORARRAY(AR20)} -> 0.00063594113 | BK20: 6 | BL20: =BN11*IF(BN11>0,1,0) -> 0 | BM20: =BO11*IF(BO11>0,1,0) -> 0 | BN20: =BP11*IF(BP11>0,1,0) -> 0 | BO20: =BQ11*IF(BQ11>0,1,0) -> 0 | BP20: =BR11*IF(BR11>0,1,0) -> 0
L21: W_h | P21: U_h | T21: b_h | W21: 1 | Z21: 1 | AD21: 1 | AE21: {=Z7:Z18-$W$39*$AE14*$W$7:$W$18} -> -0.11381919 | AF21: {=AA7:AA18-$W$39*$AE15*$W$7:$W$18} -> -0.674139 | AG21: {=AB7:AB18-$W$39*$AE16*$W$7:$W$18} -> -0.77347417 | AJ21: 2 | AK21: 0.026489288 | AM21: 0.01983562 | AN21: 0.0014490905 | AO21: 0.00091842504 | AP21: 0.00017274682 | AQ21: -0.014321267 | AR21: -0.0031918165 | AS21: -0.0010667966 | AU21: 0.0021872764 | AV21: 0.00058690103 | AW21: -0.00022136682 | AX21: 0.00096076189 | AY21: 0.0014490905 | AZ21: 0.00026074633 | BA21: 6.9964769e-05 | BB21: -3.0332633e-05 | BC21: 0.00016782159 | BD21: 0.00017274682 | BE21: -0.0048177699 | BF21: -0.0012927283 | BG21: 0.00079472616 | BH21: -0.0031836819 | BI21: -0.0031918165
L22: 1 | M22: 2 | P22: 1 | Q22: 2 | T22: 1 | V22: 1 | W22: {=TRANSPOSE(MMULT(TRANSPOSE(W7:W18),Z7:AB18)+TRANSPOSE(Z22:Z24))} -> -0.22012361 | Y22: 1 | Z22: 1 | AD22: 2 | AE22: -0.91353674 | AF22: -0.044893912 | AG22: 0.99805607 | BL22: KERNEL | BM22: Pers 2.13 | BQ22: BIAS | BR22: Pers 2.14
K23: 1 | L23: -0.507 | M23: 0.891 | O23: 1 | P23: 0.672 | Q23: 0.741 | S23: 1 | T23: 0 | V23: 2 | W23: 1.0874897 | Y23: 2 | Z23: 1 | AD23: 3 | AE23: -0.58692347 | AF23: 0.30685515 | AG23: -0.11358213 | AK23: t=3 | AU23: t=3 | BL23: 1 | BM23: 2 | BN23: 3 | BQ23: 1
K24: 2 | L24: 0.672 | M24: 0.741 | O24: 2 | P24: -0.507 | Q24: 0.891 | S24: 2 | T24: 0 | V24: 3 | W24: 1.9511892 | Y24: 3 | Z24: 1 | AD24: 4 | AE24: -0.25878442 | AF24: -0.20701093 | AG24: 0.19322479 | AJ24: Pers 2.39 | AK24: L wrt h_t | AM24: L wrt ~h_t | AN24: L wrt z_~h(t) | AO24: L wrt z_t | AP24: L wrt z_z(t) | AQ24: L wrt r_t | AR24: L wrt z_r(t) | AS24: L wrt h_t-1 | AU24: L wrt W_h | AW24: L wrt U_h | AY24: L wrt b_h | AZ24: L wrt W_z | BB24: L wrt U_z | BD24: L wrt b_z | BE24: L wrt W_r | BG24: L wrt U_r | BI24: L wrt b_r | BK24: 1 | BL24: {=FRONTEND!$M7-$W$39*SUM($BL$15:$BP$20*BV5:BZ10)} -> -0.51228313 | BM24: {=FRONTEND!$N7-$W$39*SUM($BL$15:$BP$20*BW5:CA10)} -> 0.89299962 | BN24: {=FRONTEND!$O7-$W$39*SUM($BL$15:$BP$20*BX5:CB10)} -> -0.52227575 | BP24: 1 | BQ24: =FRONTEND!$W$7-$W$39*SUM(AU56:AU61) -> 0.98709549
AD25: 5 | AE25: -0.54397741 | AF25: -0.19013645 | AG25: 0.18040577 | AK25: 1 | AM25: 1 | AN25: 1 | AO25: 1 | AP25: 1 | AQ25: 1 | AR25: 1 | AS25: 1 | AU25: 1 | AV25: 2 | AW25: 1 | AX25: 2 | AY25: 1 | AZ25: 1 | BA25: 2 | BB25: 1 | BC25: 2 | BD25: 1 | BE25: 1 | BF25: 2 | BG25: 1 | BH25: 2 | BI25: 1 | BK25: 2 | BL25: {=FRONTEND!$M8-$W$39*SUM($BL$15:$BP$20*BV6:BZ11)} -> 0.11929402 | BM25: {=FRONTEND!$N8-$W$39*SUM($BL$15:$BP$20*BW6:CA11)} -> -0.20105071 | BN25: {=FRONTEND!$O8-$W$39*SUM($BL$15:$BP$20*BX6:CB11)} -> -0.74587529
C26: Ref: apabila menggunakan cara PyTorch | K26: t=1 | W26: OUTPUT SIGMOID | Y26: Pers 2.95 | AD26: 6 | AE26: 0.60512699 | AF26: 0.88684731 | AG26: 0.76442918 | AJ26: 1 | AK26: {=AH94:AH95+_xlfn.ANCHORARRAY(AS20)} -> -0.21079132 | AM26: {=_xlfn.ANCHORARRAY(AK26)*(1-$O$41:$O$42)} -> -0.070304785 | AN26: {=_xlfn.ANCHORARRAY(AM26)*(1-$R$41:$R$42*$R$41:$R$42)} -> -0.065827102 | AO26: {=_xlfn.ANCHORARRAY(AK26)*(_xlfn.ANCHORARRAY(T35)-$R$41:$R$42)} -> 0.15856872 | AP26: {=_xlfn.ANCHORARRAY(AO26)*($O$41:$O$42*(1-$O$41:$O$42))} -> 0.035247772 | AQ26: {=MMULT(TRANSPOSE($P$23:$Q$24),_xlfn.ANCHORARRAY(AN26))*_xlfn.ANCHORARRAY(T41)} -> 0.01101776 | AR26: {=_xlfn.ANCHORARRAY(AQ26)*($L$41:$L$42*(1-$L$41:$L$42))} -> 0.0011478744 | AS26: {=_xlfn.ANCHORARRAY(AK26)*$O$41:$O$42+MMULT(TRANSPOSE($P$23:$Q$24),_xlfn.ANCHORARRAY(AN26))*$L$41:$L$42+MMULT(TRANSPOSE($P$18:$Q$19),_xlfn.ANCHORARRAY(AP26))+MMULT(TRANSPOSE($P$13:$Q$14),_xlfn.ANCHORARRAY(AR26))} -> -0.17942678 | AU26: {=MMULT(_xlfn.ANCHORARRAY(AN26),TRANSPOSE($E$14:$E$15))} -> -0.22242501 | AV26: -0.12107684 | AW26: {=MMULT(_xlfn.ANCHORARRAY(AN26),TRANSPOSE($L$41:$L$42*_xlfn.ANCHORARRAY(T35)))} -> 0.029018512 | AX26: -0.055829846 | AY26: {=_xlfn.ANCHORARRAY(AN26)} -> -0.065827102 | AZ26: {=MMULT(_xlfn.ANCHORARRAY(AP26),TRANSPOSE($E$14:$E$15))} -> 0.11909967 | BA26: 0.064831791 | BB26: {=MMULT(_xlfn.ANCHORARRAY(AP26),TRANSPOSE(_xlfn.ANCHORARRAY(T35)))} -> -0.017619887 | BC26: 0.033443155 | BD26: {=_xlfn.ANCHORARRAY(AP26)} -> 0.035247772 | BE26: {=MMULT(_xlfn.ANCHORARRAY(AR26),TRANSPOSE($E$14:$E$15))} -> 0.0038785844 | BF26: 0.0021113037 | BG26: {=MMULT(_xlfn.ANCHORARRAY(AR26),TRANSPOSE(_xlfn.ANCHORARRAY(T35)))} -> -0.00057380695 | BH26: 0.0010891054 | BI26: {=_xlfn.ANCHORARRAY(AR26)} -> 0.0011478744 | BK26: 3 | BL26: {=FRONTEND!$M9-$W$39*SUM($BL$15:$BP$20*BV7:BZ12)} -> 0.73296607 | BM26: {=FRONTEND!$N9-$W$39*SUM($BL$15:$BP$20*BW7:CA12)} -> 0.80055534 | BN26: {=FRONTEND!$O9-$W$39*SUM($BL$15:$BP$20*BX7:CB12)} -> -0.96440547
C27: H TILDE | D27: TANH | E27: H | H27: R | I27: Pers 2.32 | K27: R | L27: SIGMOID | N27: Z | O27: SIGMOID | Q27: H TILDE | R27: TANH | T27: H | W27: 1 | AD27: 7 | AE27: -0.206145 | AF27: -0.86359962 | AG27: 0.25286454 | AJ27: 2 | AK27: 0.074704525 | AM27: 0.071259958 | AN27: 2.8069293e-05 | AO27: -0.0038100114 | AP27: -0.00016757637 | AQ27: -0.048628622 | AR27: -0.004612296 | AS27: -0.0071148169 | AU27: 9.4844111e-05 | AV27: 5.16283e-05 | AW27: -1.2373765e-05 | AX27: 2.380637e-05 | AY27: 2.8069293e-05 | AZ27: -0.00056622841 | BA27: -0.00030822589 | BB27: 8.376917e-05 | BC27: -0.00015899678 | BD27: -0.00016757637 | BE27: -0.015584614 | BF27: -0.0084834698 | BG27: 0.0023056247 | BH27: -0.0043761554 | BI27: -0.004612296 | BK27: 4 | BL27: {=FRONTEND!$M10-$W$39*SUM($BL$15:$BP$20*BV8:BZ13)} -> 0.78757947 | BM27: {=FRONTEND!$N10-$W$39*SUM($BL$15:$BP$20*BW8:CA13)} -> 0.50862609 | BN27: {=FRONTEND!$O10-$W$39*SUM($BL$15:$BP$20*BX8:CB13)} -> -0.90474865
C28: 1 | D28: 1 | E28: 1 | H28: Z | I28: Pers 2.34 | K28: 1 | L28: 1 | N28: 1 | O28: 1 | Q28: 1 | R28: 1 | T28: 1 | V28: 1 | W28: =1/(1+EXP(-W22)) -> 0.44519023 | X28: gembira | AD28: 8 | AE28: 0.55644325 | AF28: 0.18384225 | AG28: -0.50633075 | BK28: 5 | BL28: {=FRONTEND!$M11-$W$39*SUM($BL$15:$BP$20*BV9:BZ14)} -> 0.41873346 | BM28: {=FRONTEND!$N11-$W$39*SUM($BL$15:$BP$20*BW9:CA14)} -> -0.4257385 | BN28: {=FRONTEND!$O11-$W$39*SUM($BL$15:$BP$20*BX9:CB14)} -> 0.29491139
C29: {=MMULT($L$23:$M$24,$C$14:$C$15)+$L$29:$L$30*MMULT($P$23:$Q$24,$L$7:$L$8)+$T$23:$T$24} -> -0.95197822 | D29: =(EXP(C29)-EXP(-C29))/(EXP(C29)+EXP(-C29)) -> -0.74067732 | E29: {=O29:O30*L7:L8+(1-O29:O30)*D29:D30} -> -0.45526208 | H29: H TILDE | I29: Pers 2.35 | J29: 1 | K29: {=MMULT($L$13:$M$14,$C$14:$C$15)+MMULT($P$13:$Q$14,$L$7:$L$8)+$T$13:$T$14} -> 3.9880876 | L29: =1/(1+EXP(-K29)) -> 0.98180217 | N29: {=MMULT($L$18:$M$19,$C$14:$C$15)+MMULT($P$18:$Q$19,$L$7:$L$8)+$T$18:$T$19} -> -1.4851299 | O29: =1/(1+EXP(-N29)) -> 0.18465383 | Q29: {=MMULT($L$23:$M$24,$C$14:$C$15)+MMULT($P$23:$Q$24,$L$29:$L$30*$L$7:$L$8)+$T$23:$T$24} -> -0.76420633 | R29: =(EXP(Q29)-EXP(-Q29))/(EXP(Q29)+EXP(-Q29)) -> -0.6435479 | T29: {=O29:O30*L7:L8+(1-O29:O30)*R29:R30} -> -0.37606797 | V29: 2 | W29: =1/(1+EXP(-W23)) -> 0.74790872 | X29: sedih | AD29: 9 | AE29: 1.0024099 | AF29: -0.94893028 | AG29: -0.90221691 | AK29: t=2 | AU29: t=2
C30: 2.8410056 | D30: =(EXP(C30)-EXP(-C30))/(EXP(C30)+EXP(-C30)) -> 0.99320973 | E30: 0.60985407 | H30: H | I30: Pers 2.37 | J30: 2 | K30: 0.95656399 | L30: =1/(1+EXP(-K30)) -> 0.72243333 | N30: -1.4205456 | O30: =1/(1+EXP(-N30)) -> 0.19457607 | Q30: 2.7351481 | R30: =(EXP(Q30)-EXP(-Q30))/(EXP(Q30)+EXP(-Q30)) -> 0.99161533 | T30: 0.6085699 | V30: 3 | W30: =1/(1+EXP(-W24)) -> 0.87557625 | X30: tegang | AD30: 10 | AE30: 0.48219641 | AF30: 0.36294738 | AG30: -0.20404052 | AJ30: Pers 2.39 | AK30: L wrt h_t | AM30: L wrt ~h_t | AN30: L wrt z_~h(t) | AO30: L wrt z_t | AP30: L wrt z_z(t) | AQ30: L wrt r_t | AR30: L wrt z_r(t) | AS30: L wrt h_t-1 | AU30: L wrt W_h | AW30: L wrt U_h | AY30: L wrt b_h | AZ30: L wrt W_z | BB30: L wrt U_z | BD30: L wrt b_z | BE30: L wrt W_r | BG30: L wrt U_r | BI30: L wrt b_r
C31: https://docs.pytorch.org/docs/2.12/generated/torch.nn.GRU.html | AD31: 11 | AE31: 0.2490857 | AF31: 0.48474232 | AG31: -0.0041866695 | AK31: 1 | AM31: 1 | AN31: 1 | AO31: 1 | AP31: 1 | AQ31: 1 | AR31: 1 | AS31: 1 | AU31: 1 | AV31: 2 | AW31: 1 | AX31: 2 | AY31: 1 | AZ31: 1 | BA31: 2 | BB31: 1 | BC31: 2 | BD31: 1 | BE31: 1 | BF31: 2 | BG31: 1 | BH31: 2 | BI31: 1 | BL31: FRONT-END
K32: t=2 | W32: LOSS | Y32: Pers 2.122 | AD32: 12 | AE32: -0.15660267 | AF32: -0.44361724 | AG32: 0.012331744 | AJ32: 1 | AK32: {=AI94:AI95+_xlfn.ANCHORARRAY(AS26)} -> -0.24679317 | AM32: {=_xlfn.ANCHORARRAY(AK32)*(1-$O$35:$O$36)} -> -0.11444663 | AN32: {=_xlfn.ANCHORARRAY(AM32)*(1-$R$35:$R$36*$R$35:$R$36)} -> -0.067118359 | AO32: {=_xlfn.ANCHORARRAY(AK32)*(_xlfn.ANCHORARRAY(T29)-$R$35:$R$36)} -> -0.065894482 | AP32: {=_xlfn.ANCHORARRAY(AO32)*($O$35:$O$36*(1-$O$35:$O$36))} -> -0.016386959 | AQ32: {=MMULT(TRANSPOSE($P$23:$Q$24),_xlfn.ANCHORARRAY(AN32))*_xlfn.ANCHORARRAY(T29)} -> 0.017102951 | AR32: {=_xlfn.ANCHORARRAY(AQ32)*($L$35:$L$36*(1-$L$35:$L$36))} -> 0.001491072 | AS32: {=_xlfn.ANCHORARRAY(AK32)*$O$35:$O$36+MMULT(TRANSPOSE($P$23:$Q$24),_xlfn.ANCHORARRAY(AN32))*$L$35:$L$36+MMULT(TRANSPOSE($P$18:$Q$19),_xlfn.ANCHORARRAY(AP32))+MMULT(TRANSPOSE($P$13:$Q$14),_xlfn.ANCHORARRAY(AR32))} -> -0.17845955 | AU32: {=MMULT(_xlfn.ANCHORARRAY(AN32),TRANSPOSE($D$14:$D$15))} -> -0.21315282 | AV32: -0.056007696 | AW32: {=MMULT(_xlfn.ANCHORARRAY(AN32),TRANSPOSE($L$35:$L$36*_xlfn.ANCHORARRAY(T29)))} -> 0.022805478 | AX32: -0.030031385 | AY32: {=_xlfn.ANCHORARRAY(AN32)} -> -0.067118359 | AZ32: {=MMULT(_xlfn.ANCHORARRAY(AP32),TRANSPOSE($D$14:$D$15))} -> -0.0520413 | BA32: -0.013674289 | BB32: {=MMULT(_xlfn.ANCHORARRAY(AP32),TRANSPOSE(_xlfn.ANCHORARRAY(T29)))} -> 0.0061626106 | BC32: -0.0099726101 | BD32: {=_xlfn.ANCHORARRAY(AP32)} -> -0.016386959 | BE32: {=MMULT(_xlfn.ANCHORARRAY(AR32),TRANSPOSE($D$14:$D$15))} -> 0.0047353095 | BF32: 0.0012442424 | BG32: {=MMULT(_xlfn.ANCHORARRAY(AR32),TRANSPOSE(_xlfn.ANCHORARRAY(T29)))} -> -0.00056074443 | BH32: 0.00090742153 | BI32: {=_xlfn.ANCHORARRAY(AR32)} -> 0.001491072 | BL32: KONVOLUSI HORIZONTAL | BT32: 0 | BU32: 0 | BV32: 0
C33: H TILDE | D33: TANH | E33: H | K33: R | L33: SIGMOID | N33: Z | O33: SIGMOID | Q33: H TILDE | R33: TANH | T33: H | W33: 1 | X33: t_n | AJ33: 2 | AK33: 0.16312855 | AM33: 0.14273731 | AN33: 0.00073927736 | AO33: -0.063430431 | AP33: -0.0069377531 | AQ33: -0.029866181 | AR33: -0.0058139468 | AS33: -0.033806468 | AU33: 0.0023477788 | AV33: 0.00061689861 | AW33: -0.00025119168 | AX33: 0.00033078168 | AY33: 0.00073927736 | AZ33: -0.022032745 | BA33: -0.0057892889 | BB33: 0.0026090668 | BC33: -0.0042221077 | BD33: -0.0069377531 | BE33: -0.018463788 | BF33: -0.0048515157 | BG33: 0.0021864392 | BH33: -0.003538193 | BI33: -0.0058139468 | BL33: KE RELU | BM33: Pers 2.17 | BT33: 0 | BU33: {=FRONTEND!$B$26:$B$31} -> 0.36548104 | BV33: 0
C34: 1 | D34: 1 | E34: 1 | K34: 1 | L34: 1 | N34: 1 | O34: 1 | Q34: 1 | R34: 1 | T34: 1 | V34: n=1 | W34: =((2/(1+DATA!$I$16))*X34*LN(W28)+((2*DATA!$I$16)/(1+DATA!$I$16))*(1-X34)*LN(1-W28)) -> -1.4510754 | X34: 1 | AE34: BIAS | AF34: Pers 2.101 | BL34: 1 | BT34: 0 | BU34: -0.24318937 | BV34: 0
C35: {=MMULT($L$23:$M$24,$D$14:$D$15)+$L$35:$L$36*MMULT($P$23:$Q$24,_xlfn.ANCHORARRAY(T29))+$T$23:$T$24} -> -0.68750818 | D35: =(EXP(C35)-EXP(-C35))/(EXP(C35)+EXP(-C35)) -> -0.59637882 | E35: {=O35:O36*_xlfn.ANCHORARRAY(T29)+(1-O35:O36)*D35:D36} -> -0.47823382 | J35: 1 | K35: {=MMULT($L$13:$M$14,$D$14:$D$15)+MMULT($P$13:$Q$14,_xlfn.ANCHORARRAY(T29))+$T$13:$T$14} -> 2.2368127 | L35: =1/(1+EXP(-K35)) -> 0.90350694 | N35: {=MMULT($L$18:$M$19,$D$14:$D$15)+MMULT($P$18:$Q$19,_xlfn.ANCHORARRAY(T29))+$T$18:$T$19} -> 0.14531521 | O35: =1/(1+EXP(-N35)) -> 0.53626501 | Q35: {=MMULT($L$23:$M$24,$D$14:$D$15)+MMULT($P$23:$Q$24,$L$35:$L$36*_xlfn.ANCHORARRAY(T29))+$T$23:$T$24} -> -0.76339244 | R35: =(EXP(Q35)-EXP(-Q35))/(EXP(Q35)+EXP(-Q35)) -> -0.64307083 | T35: {=O35:O36*_xlfn.ANCHORARRAY(T29)+(1-O35:O36)*R35:R36} -> -0.49988654 | V35: 2 | W35: =((2/(1+DATA!$I$17))*X35*LN(W29)+((2*DATA!$I$17)/(1+DATA!$I$17))*(1-X35)*LN(1-W29)) -> -1.0498774 | X35: 0 | AE35: 1 | AK35: t=1 | AU35: t=1 | BK35: 1 | BL35: =AV56*IF(AV56>0,1,0) -> 0 | BT35: 0 | BU35: 0.086633902 | BV35: 0
C36: 3.2913092 | D36: =(EXP(C36)-EXP(-C36))/(EXP(C36)+EXP(-C36)) -> 0.99723539 | E36: 0.94865179 | J36: 2 | K36: 1.0213249 | L36: =1/(1+EXP(-K36)) -> 0.7352306 | N36: -1.9459006 | O36: =1/(1+EXP(-N36)) -> 0.12500104 | Q36: 3.3233939 | R36: =(EXP(Q36)-EXP(-Q36))/(EXP(Q36)+EXP(-Q36)) -> 0.997407 | T36: 0.94880195 | V36: 3 | W36: =((2/(1+DATA!$I$18))*X36*LN(W30)+((2*DATA!$I$18)/(1+DATA!$I$18))*(1-X36)*LN(1-W30)) -> -0.2093757 | X36: 1 | AD36: 1 | AE36: =Z22-$W$39*$AE14 -> 1.033161 | AJ36: Pers 2.39 | AK36: L wrt h_t | AM36: L wrt ~h_t | AN36: L wrt z_~h(t) | AO36: L wrt z_t | AP36: L wrt z_z(t) | AQ36: L wrt r_t | AR36: L wrt z_r(t) | AS36: L wrt h_t-1 | AU36: L wrt W_h | AW36: L wrt U_h | AY36: L wrt b_h | AZ36: L wrt W_z | BB36: L wrt U_z | BD36: L wrt b_z | BE36: L wrt W_r | BG36: L wrt U_r | BI36: L wrt b_r | BK36: 2 | BL36: =AV57*IF(AV57>0,1,0) -> 0 | BT36: 0 | BU36: -0.8436868 | BV36: 0
V37: avg | W37: =-1*SUM(W34:W36)/3 -> 0.90344282 | AD37: 2 | AE37: =Z23-$W$39*$AE15 -> 0.99484201 | AK37: 1 | AM37: 1 | AN37: 1 | AO37: 1 | AP37: 1 | AQ37: 1 | AR37: 1 | AS37: 1 | AU37: 1 | AV37: 2 | AW37: 1 | AX37: 2 | AY37: 1 | AZ37: 1 | BA37: 2 | BB37: 1 | BC37: 2 | BD37: 1 | BE37: 1 | BF37: 2 | BG37: 1 | BH37: 2 | BI37: 1 | BK37: 3 | BL37: =AV58*IF(AV58>0,1,0) -> 0 | BT37: 0 | BU37: 0.17422067 | BV37: 0
K38: t=3 | AD38: 3 | AE38: =Z24-$W$39*$AE16 -> 1.0074368 | AJ38: 1 | AK38: {=AJ94:AJ95+_xlfn.ANCHORARRAY(AS32)} -> -0.17526758 | AM38: {=_xlfn.ANCHORARRAY(AK38)*(1-$O$29:$O$30)} -> -0.14290375 | AN38: {=_xlfn.ANCHORARRAY(AM38)*(1-$R$29:$R$30*$R$29:$R$30)} -> -0.083719605 | AO38: {=_xlfn.ANCHORARRAY(AK38)*(L7:L8-$R$29:$R$30)} -> -0.25388348 | AP38: {=_xlfn.ANCHORARRAY(AO38)*($O$29:$O$30*(1-$O$29:$O$30))} -> -0.038223884 | AQ38: {=MMULT(TRANSPOSE($P$23:$Q$24),_xlfn.ANCHORARRAY(AN38))*$L$7:$L$8} -> -0.045492445 | AR38: {=_xlfn.ANCHORARRAY(AQ38)*($L$29:$L$30*(1-$L$29:$L$30))} -> -0.00081279835 | AS38: {=_xlfn.ANCHORARRAY(AK38)*$O$29:$O$30+MMULT(TRANSPOSE($P$23:$Q$24),_xlfn.ANCHORARRAY(AN38))*$L$29:$L$30+MMULT(TRANSPOSE($P$18:$Q$19),_xlfn.ANCHORARRAY(AP38))+MMULT(TRANSPOSE($P$13:$Q$14),_xlfn.ANCHORARRAY(AR38))} -> -0.099744599 | AU38: {=MMULT(_xlfn.ANCHORARRAY(AN38),TRANSPOSE($C$14:$C$15))} -> -0.33736218 | AV38: -0.11939958 | AW38: {=MMULT(_xlfn.ANCHORARRAY(AN38),TRANSPOSE($L$29:$L$30*L7:L8))} -> -0.066167852 | AX38: 0.059090751 | AY38: {=_xlfn.ANCHORARRAY(AN38)} -> -0.083719605 | AZ38: {=MMULT(_xlfn.ANCHORARRAY(AP38),TRANSPOSE($C$14:$C$15))} -> -0.15402955 | BA38: -0.0545143 | BB38: {=MMULT(_xlfn.ANCHORARRAY(AP38),TRANSPOSE(L7:L8))} -> -0.030770227 | BC38: 0.037344735 | BD38: {=_xlfn.ANCHORARRAY(AP38)} -> -0.038223884 | BE38: {=MMULT(_xlfn.ANCHORARRAY(AR38),TRANSPOSE($C$14:$C$15))} -> -0.0032753072 | BF38: -0.0011592002 | BG38: {=MMULT(_xlfn.ANCHORARRAY(AR38),TRANSPOSE(L7:L8))} -> -0.00065430267 | BH38: 0.00079410399 | BI38: {=_xlfn.ANCHORARRAY(AR38)} -> -0.00081279835 | BK38: 4 | BL38: =AV59*IF(AV59>0,1,0) -> 0 | BT38: 0 | BU38: 0.46054055 | BV38: 0
C39: H TILDE | D39: TANH | E39: H | K39: R | L39: SIGMOID | N39: Z | O39: SIGMOID | Q39: H TILDE | R39: TANH | T39: H | V39: lr= | W39: 0.1 | AJ39: 2 | AK39: 0.037069652 | AM39: 0.029856785 | AN39: 0.00049857961 | AO39: -0.072975885 | AP39: -0.011436505 | AQ39: 0.060175377 | AR39: 0.012066572 | AS39: -0.070101509 | AU39: 0.0020091101 | AV39: 0.00071106637 | AW39: 0.00039405277 | AX39: -0.00035190615 | AY39: 0.00049857961 | AZ39: -0.046085315 | BA39: -0.016310563 | BB39: -0.0092063866 | BC39: 0.011173465 | BD39: -0.011436505 | BE39: 0.048624275 | BF39: 0.017209155 | BG39: 0.0097135904 | BH39: -0.011789041 | BI39: 0.012066572 | BK39: 5 | BL39: =AV60*IF(AV60>0,1,0) -> 0 | BT39: 0 | BU39: 0 | BV39: 0
C40: 1 | D40: 1 | E40: 1 | K40: 1 | L40: 1 | N40: 1 | O40: 1 | Q40: 1 | R40: 1 | T40: 1 | AE40: KE POOLING | BK40: 6 | BL40: =AV61*IF(AV61>0,1,0) -> 0.003636655
C41: {=MMULT($L$23:$M$24,$E$14:$E$15)+$L$41:$L$42*MMULT($P$23:$Q$24,_xlfn.ANCHORARRAY(T35))+$T$23:$T$24} -> 0.24947848 | D41: =(EXP(C41)-EXP(-C41))/(EXP(C41)+EXP(-C41)) -> 0.24442836 | E41: {=O41:O42*_xlfn.ANCHORARRAY(T35)+(1-O41:O42)*D41:D42} -> -0.25163676 | J41: 1 | K41: {=MMULT($L$13:$M$14,$E$14:$E$15)+MMULT($P$13:$Q$14,_xlfn.ANCHORARRAY(T35))+$T$13:$T$14} -> 2.0101495 | L41: =1/(1+EXP(-K41)) -> 0.8818586 | N41: {=MMULT($L$18:$M$19,$E$14:$E$15)+MMULT($P$18:$Q$19,_xlfn.ANCHORARRAY(T35))+$T$18:$T$19} -> 0.69227178 | O41: =1/(1+EXP(-N41)) -> 0.6664721 | Q41: {=MMULT($L$23:$M$24,$E$14:$E$15)+MMULT($P$23:$Q$24,$L$41:$L$42*_xlfn.ANCHORARRAY(T35))+$T$23:$T$24} -> 0.25794026 | R41: =(EXP(Q41)-EXP(-Q41))/(EXP(Q41)+EXP(-Q41)) -> 0.25236798 | T41: {=O41:O42*_xlfn.ANCHORARRAY(T35)+(1-O41:O42)*R41:R42} -> -0.24898868 | AE41: 1 | AF41: Pers 2.102 | AU41: SUM t=1,2,...,6 | AY41: Pers 2.52 | BD41: Pers 2.55 | BI41: Pers 2.58
...

Sheet ATTN-BE
C2: CONCATENATE | F2: dk | G2: =$G$4/$G$5 -> 1 | J2: FEED-FORWARD | AG2: FEED-FORWARD | AO2: BACKPROPAGATION | AU2: BACKPROPAGATION | CC2: FRONT-END
C3: 1 | D3: 2 | F3: dv | G3: =$G$4/$G$5 -> 1 | J3: MHA | AG3: CLASSIFIER | AO3: CLASSIFIER | AU3: POSITION-WISE FFN | CC3: KONVOLUSI VERTIKAL
B4: 1 | C4: {=FRONTEND!M49:N54} -> 4.0296677 | D4: 1.4261842 | F4: d_model | G4: 2 | H4: Pers 2.62 | J4: head_1 | L4: Pers 2.63 | N4: Pers 2.63 | P4: head_1 | AD4: head_1 | CC4: KE MAX-POOLING | CE4: HASIL | CF4: Pers 2.10 | CK4: 0 | CL4: 0 | CM4: 0 | CN4: 0 | CO4: 0 | CP4: 0 | CQ4: 0 | CR4: 0 | CS4: 0 | CT4: 0 | CU4: 0
B5: 2 | C5: 3.1757752 | D5: 0.83446165 | F5: h | G5: 2 | I5: Pers 2.63 | J5: Q WQ | L5: K WK | N5: V WV | P5: QK^T | W5: SOFTMAX | AD5: SOFTMAX V | AE5: Pers 2.60 | AG5: INPUT | AJ5: BOBOT | AO5: L wrt y_n | AP5: Pers 2.96 | AU5: W2 | AV5: Pers 2.67 | AX5: b2 | AY5: Pers 2.68 | CC5: 1 | CD5: argmax | CE5: 1 | CF5: 2 | CG5: 3 | CH5: 4 | CI5: 5 | CK5: 0 | CL5: 0 | CM5: 0 | CN5: 0 | CO5: 0 | CP5: 0 | CQ5: 0 | CR5: 0 | CS5: 0 | CT5: 0 | CU5: 0
B6: 3 | C6: 3.3789276 | D6: 1.839316 | F6: d_ff | G6: 2 | J6: 1 | L6: 1 | N6: 1 | P6: 1 | Q6: 2 | R6: 3 | S6: 4 | T6: 5 | U6: 6 | W6: 1 | X6: 2 | Y6: 3 | Z6: 4 | AA6: 5 | AB6: 6 | AD6: 1 | AG6: 1 | AJ6: 1 | AK6: 2 | AL6: 3 | AO6: 1 | AU6: 1 | AV6: 2 | AX6: 1 | AY6: 2 | CB6: 1 | CC6: {=CA85:CA90} -> -0.19032161 | CD6: =MATCH(MAX(FRONTEND!$M28:$Q28),FRONTEND!$M28:$Q28,0) -> 4 | CE6: =IF($CD6=CE$5,$CC6,0) -> 0 | CF6: =IF($CD6=CF$5,$CC6,0) -> 0 | CG6: =IF($CD6=CG$5,$CC6,0) -> 0 | CH6: =IF($CD6=CH$5,$CC6,0) -> -0.19032161 | CI6: =IF($CD6=CI$5,$CC6,0) -> 0 | CK6: 0 | CL6: 0 | CM6: 0 | CN6: 0 | CO6: 0 | CP6: 0 | CQ6: 0 | CR6: 0 | CS6: 0 | CT6: 0 | CU6: 0
B7: 4 | C7: 1.5094132 | D7: 0.40501336 | I7: 1 | J7: {=MMULT($C$14:$D$19,C25:C26)} -> -1.3385314 | L7: {=MMULT($C$14:$D$19,E25:E26)} -> -0.11812804 | N7: {=MMULT($C$14:$D$19,G25:G26)} -> -1.7817101 | P7: {=MMULT(_xlfn.ANCHORARRAY(J7),TRANSPOSE(_xlfn.ANCHORARRAY(L7)))/SQRT($G$2)} -> 0.15811809 | Q7: -0.85963907 | R7: -0.96082048 | S7: -1.4736333 | T7: -2.1737682 | U7: 0.35613756 | W7: {=EXP(P7)/SUM(EXP($P7:$U7))} -> 0.31252772 | X7: {=EXP(Q7)/SUM(EXP($P7:$U7))} -> 0.11294896 | Y7: {=EXP(R7)/SUM(EXP($P7:$U7))} -> 0.10207977 | Z7: {=EXP(S7)/SUM(EXP($P7:$U7))} -> 0.061126276 | AA7: {=EXP(T7)/SUM(EXP($P7:$U7))} -> 0.030350316 | AB7: {=EXP(U7)/SUM(EXP($P7:$U7))} -> 0.38096696 | AD7: {=MMULT(W7:AB12,_xlfn.ANCHORARRAY(N7))} -> -1.2059823 | AF7: 1 | AG7: =U47 -> 3.8524777 | AI7: 1 | AJ7: -0.134 | AK7: -0.671 | AL7: -0.778 | AN7: 1 | AO7: =-1/3*((2/(1+DATA!$I$16))*AH34/AG28-((2*DATA!$I$16)/(1+DATA!$I$16))*(1-AH34)*(1-AG28)) -> -1.558861 | AT7: 1 | AU7: {=C47:D48-$AG$39*MMULT(TRANSPOSE($M$38:$N$43),$AO$75:$AP$80)} -> -0.77676932 | AV7: -0.80272199 | AX7: =F47-$AG$39*SUM(AO75:AO80) -> 0.96414111 | AY7: =G47-$AG$39*SUM(AP75:AP80) -> 1.026151 | CB7: 2 | CC7: 0.076334272 | CD7: =MATCH(MAX(FRONTEND!$M29:$Q29),FRONTEND!$M29:$Q29,0) -> 2 | CE7: =IF($CD7=CE$5,$CC7,0) -> 0 | CF7: =IF($CD7=CF$5,$CC7,0) -> 0.076334272 | CG7: =IF($CD7=CG$5,$CC7,0) -> 0 | CH7: =IF($CD7=CH$5,$CC7,0) -> 0 | CI7: =IF($CD7=CI$5,$CC7,0) -> 0 | CK7: 0 | CL7: 0 | CM7: 0 | CN7: {=FRONTEND!$B$4:$F$9} -> 0.098070128 | CO7: 0.76989837 | CP7: 1.0888675 | CQ7: 0.41864133 | CR7: -0.54807215 | CS7: 0 | CT7: 0 | CU7: 0
B8: 5 | C8: 4.5198657 | D8: 0.53701995 | I8: 2 | J8: -2.253074 | L8: 0.64222555 | N8: -1.0997438 | P8: 0.2661512 | Q8: -1.4469817 | R8: -1.6172946 | S8: -2.4804832 | T8: -3.6589806 | U8: 0.59946614 | W8: {=EXP(P8)/SUM(EXP($P8:$U8))} -> 0.35563965 | X8: {=EXP(Q8)/SUM(EXP($P8:$U8))} -> 0.064121848 | Y8: {=EXP(R8)/SUM(EXP($P8:$U8))} -> 0.054080422 | Z8: {=EXP(S8)/SUM(EXP($P8:$U8))} -> 0.022811928 | AA8: {=EXP(T8)/SUM(EXP($P8:$U8))} -> 0.0070201615 | AB8: {=EXP(U8)/SUM(EXP($P8:$U8))} -> 0.49632599 | AD8: -1.3104404 | AF8: 2 | AG8: =U48 -> 3.7740177 | AI8: 2 | AJ8: -0.945 | AK8: -0.04 | AL8: 0.991 | AN8: 2 | AO8: =-1/3*((2/(1+DATA!$I$16))*AH35/AG29-((2*DATA!$I$16)/(1+DATA!$I$16))*(1-AH35)*(1-AG29)) -> 0.066442273 | AT8: 2 | AU8: -0.77099298 | AV8: 0.11136104 | CB8: 3 | CC8: -0.15458802 | CD8: =MATCH(MAX(FRONTEND!$M30:$Q30),FRONTEND!$M30:$Q30,0) -> 3 | CE8: =IF($CD8=CE$5,$CC8,0) -> 0 | CF8: =IF($CD8=CF$5,$CC8,0) -> 0 | CG8: =IF($CD8=CG$5,$CC8,0) -> -0.15458802 | CH8: =IF($CD8=CH$5,$CC8,0) -> 0 | CI8: =IF($CD8=CI$5,$CC8,0) -> 0 | CK8: 0 | CL8: 0 | CM8: 0 | CN8: 0.39479458 | CO8: 0.76298403 | CP8: -1.5092547 | CQ8: 0.78695236 | CR8: -1.6514231 | CS8: 0 | CT8: 0 | CU8: 0
